Workbook

Sheet Summary
A1: Summary of Selected Results from Energy Transfer-related natural gas releases (2010-present)
A3: Number of Incidents | B3: =count('PHMSA Records'!A:A) -> 177 | E3: Impacts
A4: Start of Time Period | B4: 40179 | E4: Injuries | F4: =countif('PHMSA Records'!AG:AG, "YES") -> 2
A5: End of Time Period | B5: 45838 | E5: Deaths | F5: =countif('PHMSA Records'!Z:Z, "YES") -> 1
A6: Average Number of Days Between Incidents | B6: =(B5-B4)/B3 -> 31.971751 | E6: Ignition | F6: =countif('PHMSA Records'!AW:AW, "YES") -> 26
E7: Explosion | F7: =countif('PHMSA Records'!BB:BB, "YES") -> 8
A8: Total Volume (Unintentional Release) | E8: Total Property Damage | F8: =sum('PHMSA Records'!FW:FW) -> 100650634
A9: in thousand cubic feet (Mcf) | B9: =sum('PHMSA Records'!W:W) -> 6802170.1
A10: in million cubic feet (MMcf) | B10: =B9/1000 -> 6802.1701 | E10: Causes
A11: Total Volume (Intentional Release) | E11: Equipment Failure | F11: =countif('PHMSA Records'!IN:IN, "EQUIPMENT FAILURE") -> 54
A12: in thousand cubic feet (Mcf) | B12: =sum('PHMSA Records'!X:X) -> 700510.98 | E12: Corrosion | F12: =countif('PHMSA Records'!IN:IN, "CORROSION FAILURE") -> 52
A13: in million cubic feet (MMcf) | B13: =B12/1000 -> 700.51098 | E13: Material Failure of Pipe or Weld | F13: =countif('PHMSA Records'!IN:IN, "MATERIAL FAILURE OF PIPE OR WELD") -> 18
E14: Other Accident Cause | F14: =countif('PHMSA Records'!IN:IN, "OTHER INCIDENT CAUSE") -> 16
A15: Report Status | E15: Natural Force Damage | F15: =countif('PHMSA Records'!IN:IN, "NATURAL FORCE DAMAGE") -> 15
A16: Original | B16: =countif('PHMSA Records'!F:F, "ORIGINAL") -> 12 | E16: Excavation Damage | F16: =countif('PHMSA Records'!IN:IN, "EXCAVATION DAMAGE") -> 10
A17: Original Final | B17: =countif('PHMSA Records'!F:F, "ORIGINAL FINAL") -> 37 | E17: Incorrect Operation | F17: =countif('PHMSA Records'!IN:IN, "INCORRECT OPERATION") -> 8
A18: Supplemental | B18: =countif('PHMSA Records'!F:F, "SUPPLEMENTAL") -> 0 | E18: Other Outside Force Damage | F18: =countif('PHMSA Records'!IN:IN, "OTHER OUTSIDE FORCE DAMAGE") -> 4
A19: Supplemental Final | B19: =countif('PHMSA Records'!F:F, "SUPPLEMENTAL FINAL") -> 128

Sheet PHMSA Records
B1: REPORT_RECEIVED_DATE | C1: IYEAR | D1: REPORT_NUMBER | E1: SUPPLEMENTAL_NUMBER | F1: REPORT_TYPE | G1: OPERATOR_ID | H1: NAME | I1: OPERATOR_STREET_ADDRESS | J1: OPERATOR_CITY_NAME | K1: OPERATOR_STATE_ABBREVIATION | L1: OPERATOR_POSTAL_CODE | M1: LOCAL_DATETIME | N1: TIME_ZONE | O1: DAYLIGHT_SAVINGS_IND | P1: LOCATION_LATITUDE | Q1: LOCATION_LONGITUDE | R1: NRC_RPT_NUM | S1: NRC_RPT_DATETIME | T1: ADDITIONAL_NRC_REPORT_NUMBERS | U1: COMMODITY_RELEASED_TYPE | V1: COMMODITY_DETAILS | W1: UNINTENTIONAL_RELEASE | X1: INTENTIONAL_RELEASE | Y1: ACCOMPANYING_LIQUID | Z1: FATALITY_IND | AA1: NUM_EMP_FATALITIES | AB1: NUM_CONTR_FATALITIES | AC1: NUM_ER_FATALITIES | AD1: NUM_WORKER_FATALITIES | AE1: NUM_GP_FATALITIES | AF1: FATAL | AG1: INJURY_IND | AH1: NUM_EMP_INJURIES | AI1: NUM_CONTR_INJURIES | AJ1: NUM_ER_INJURIES | AK1: NUM_WORKER_INJURIES | AL1: NUM_GP_INJURIES | AM1: INJURE | AN1: STATUS_WHEN_IDENTIFIED | AO1: SHUTDOWN_DUE_ACCIDENT_IND | AP1: SHUTDOWN_EXPLAIN | AQ1: SHUTDOWN_DATETIME | AR1: RESTART_DATETIME | AS1: STILL_SHUTDOWN_IND | AT1: COMMUNICATION_STATE_FED_IND | AU1: PARTY_INITIATED_COMMUNICATION | AV1: INITIAL_RESPONDER_COM_DATETIME | AW1: IGNITE_IND | AX1: IGNITE_DATETIME | AY1: HOW_EXTINGUISHED | AZ1: HOW_EXTINGUISHED_OTHER_DETAIL | BA1: GAS_CONSUMED_BY_FIRE_IN_MCF | BB1: EXPLODE_IND | BC1: UPSTREAM_ACTION_TAKEN | BD1: UPSTREAM_OPRTNL_CNTRL_DETAIL | BE1: UPSTREAM_VALVE_CLOSE_DATETIME | BF1: DOWNSTREAM_ACTION_TAKEN | BG1: DOWNSTREAM_OPRTNL_CNTRL_DETAIL | BH1: DOWNSTREAM_VLV_CLOSE_DATETIME | BI1: NUM_PUB_EVACUATED | BJ1: INCIDENT_IDENTIFIED_DATETIME | BK1: ON_SITE_DATETIME | BL1: CONFIRMED_DISCOVERY_DATETIME | BM1: ON_OFF_SHORE | BN1: ONSHORE_STATE_ABBREVIATION | BO1: ONSHORE_POSTAL_CODE | BP1: ONSHORE_CITY_NAME | BQ1: ONSHORE_COUNTY_NAME | BR1: DESIGNATED_LOCATION | BS1: DESIGNATED_NAME | BT1: PIPE_FAC_NAME | BU1: SEGMENT_NAME | BV1: FEDERAL | BW1: LOCATION_TYPE | BX1: INCIDENT_AREA_TYPE | BY1: INCIDENT_AREA_SUBTYPE | BZ1: INCIDENT_AREA_DETAILS | CA1: DEPTH_OF_COVER | CB1: OTHER_UNDERGROUND_FACILITIES | CC1: CROSSING | CD1: BRIDGE_CROSSING_IND | CE1: BRIDGE_TYPE | CF1: RAILROAD_CROSSING_IND | CG1: RAILROAD_TYPE | CH1: ROAD_CROSSING_IND | CI1: ROAD_TYPE | CJ1: WATER_CROSSING_IND | CK1: WATER_TYPE | CL1: WATER_NAME | CM1: WATER_DEPTH | CN1: WATER_SUBTYPE | CO1: CROSSING_100_FEET | CP1: OFF_WATER_DEPTH | CQ1: OFF_ACCIDENT_ORIGIN | CR1: OFFSHORE_STATE_ABBREVIATION | CS1: OFF_INSTATE_AREA | CT1: OFF_INSTATE_BLOCK | CU1: OFFSHORE_COUNTY_NAME | CV1: OCS_TYPE | CW1: OFF_OCS_AREA | CX1: OFF_OCS_BLOCK | CY1: OFF_AREA_ACCIDENT_TYPE | CZ1: PIPE_FACILITY_TYPE | DA1: SYSTEM_PART_INVOLVED | DB1: ITEM_INVOLVED | DC1: PIPE_TYPE | DD1: PIPE_DIAMETER | DE1: PUDDLE_WELD_IND | DF1: PIPE_WALL_THICKNESS | DG1: PIPE_SMYS | DH1: PIPE_SPECIFICATION | DI1: PIPE_SEAM_TYPE | DJ1: PIPE_SEAM_DETAILS | DK1: PIPE_MANUFACTURER | DL1: PIPE_COATING_TYPE | DM1: PIPE_COATING_DETAILS | DN1: COATING_APPLIED_IND | DO1: PLASTIC_TYPE | DP1: PLASTIC_DETAILS | DQ1: PLASTIC_SDR | DR1: WT_PLASTIC | DS1: WT_PLASTIC_UNKNOWN_IND | DT1: MATERIAL_PE_PIPE_CODE | DU1: PLASTIC_PE_UNKNOWN_IND | DV1: WELD_SUBTYPE | DW1: WELD_DETAILS | DX1: DIFFERENT_GIRTH_WELD_IND | DY1: DIFF_GIRTH_WELD_WALL_THICKNESS | DZ1: DIFF_GIRTH_WELD_SMYS | EA1: DIFF_GIRTH_WELD_SPECIFICATION | EB1: DIFF_GIRTH_WELD_SEAM_TYPE | EC1: DIFF_GIRTH_WELD_SEAM_DETAIL | ED1: DIFF_GIRTH_WELD_MANUFACTURER | EE1: DIFF_GIRTH_WELD_COATING_TYPE | EF1: DIFF_GIRTH_WELD_COATING_DETAIL | EG1: DIFF_GIRTH_WELD_CTNG_APPLD_IND | EH1: VALVE_TYPE | EI1: VALVE_MAINLINE_TYPE | EJ1: VALVE_MAINLINE_DETAILS | EK1: VALVE_MANUFACTURER | EL1: TUBING_MATERIAL | EM1: TUBING_TYPE | EN1: ITEM_INVOLVED_DETAILS | EO1: INSTALLATION_YEAR | EP1: MANUFACTURED_YEAR | EQ1: MATERIAL_INVOLVED | ER1: MATERIAL_DETAILS | ES1: RELEASE_TYPE | ET1: PUNCTURE_AXIAL | EU1: PUNCTURE_CIRCUM | EV1: LEAK_TYPE | EW1: LEAK_TYPE_OTHER | EX1: RUPTURE_ORIENT | EY1: RUPTURE_DETAILS | EZ1: RUPTURE_LENGTH | FA1: RUPTURE_WIDTH | FB1: RELEASE_TYPE_DETAILS | FC1: CLASS_LOCATION_TYPE | FD1: COULD_BE_HCA | FE1: DETERMINATION_METHOD | FF1: PIR_RADIUS | FG1: NOT_FLAMMABLE_IND | FH1: HEAT_DAMAGE_IND | FI1: NON_HEAT_DAMAGE_IND | FJ1: HCA_FATALITIES_IND | FK1: FATAL_INJURE_CAUSE | FL1: DID_OCCUR_IN_MCA_IND | FM1: MCA_BUILDNG_HUMAN_OCCUPY_IND | FN1: MCA_PAVED_SURFACE_FREEWAY_IND | FO1: EST_COST_OPER_PAID | FP1: EST_COST_UNINTENTIONAL_RELEASE | FQ1: EST_COST_INTENTIONAL_RELEASE | FR1: EST_COST_PROP_DAMAGE | FS1: EST_COST_EMERGENCY | FT1: EST_COST_OTHER | FU1: EST_COST_OTHER_DETAILS | FV1: GAS_COST_IN_MCF | FW1: PRPTY | FX1: NUM_PERSONS_HOSP_NOT_OVNGHT | FY1: NUM_INJURED_TREATED_BY_EMT | FZ1: NUM_RESIDENT_BUILDING_AFFCTD | GA1: NUM_BUSINESS_BUILDING_AFFCTD | GB1: WILDLIFE_IMPACT_IND | GC1: FISH_AQUATIC_IMPACT_IND | GD1: BIRDS_IMPACT_IND | GE1: TERRESTRIAL_IMPACT_IND | GF1: ACCIDENT_PSIG | GG1: GAS_FLOW_IN_PIPE_IN_MCF | GH1: MOP_PSIG | GI1: MOP_CFR_SECTION | GJ1: MOP_CFR_SECTION_DETAILS | GK1: MAOP_ESTABLISHED_DATE | GL1: MAOP_REVERSAL_FLOW_IND | GM1: ACCIDENT_PRESSURE | GN1: PRESSURE_RESTRICTION_IND | GO1: EXCEED_RESTRICTION_IND | GP1: PHMSA_RESTRICTION_IND | GQ1: GAS_REQUIRED_ODORIZED_IND | GR1: GAS_ODORIZED_IND | GS1: UPSTREAM_VALVE_TYPE_IND | GT1: DOWNSTREAM_VALVE_TYPE_IND | GU1: LENGTH_SEGMENT_ISOLATED | GV1: INTERNAL_INSPECTION_IND | GW1: DIAMETER_CHANGE_IND | GX1: UNSUITABLE_MAINLINE_IND | GY1: TIGHT_MITERED_IND | GZ1: OTHER_RESTRICTIONS_IND | HA1: EXTRA_THICK_WALL_IND | HB1: OTHER_INSPECTION_IND | HC1: INTERNAL_INSPECTION_DETAILS | HD1: OPERATION_COMPLICATIONS_IND | HE1: EXCESSIVE_DEBRIS_IND | HF1: LOW_OP_PRESSURE_IND | HG1: LOW_FLOW_IND | HH1: INCOMPAT_COMMOD_IND | HI1: OTHER_COMPLICATIONS_IND | HJ1: INSPECT_COMP_DETAILS | HK1: PIPELINE_FUNCTION | HL1: SCADA_IN_PLACE_IND | HM1: SCADA_OPERATING_IND | HN1: SCADA_FUNCTIONAL_IND | HO1: SCADA_DETECTION_IND | HP1: SCADA_CONF_IND | HQ1: ACCIDENT_IDENTIFIER | HR1: ACCIDENT_DETAILS | HS1: OPERATOR_TYPE | HT1: INVESTIGATION_STATUS | HU1: INVESTIGATION_STATUS_DETAILS | HV1: INVEST_SCHEDULE_IND | HW1: INVEST_NO_SCHEDULE_IND | HX1: INVEST_NO_SCHEDULE_IND_DETAILS | HY1: INVEST_NO_CONTROL_ROOM_IND | HZ1: INVEST_NO_CONTROLLER_IND | IA1: INVEST_INCORRECT_ACTION_IND | IB1: INVEST_FATIGUE_IND | IC1: INVEST_INCORRECT_PROCEDURE_IND | ID1: INVEST_INCORRECT_CONTROL_IND | IE1: INVEST_MAINT_IND | IF1: INVEST_OTHER_IND | IG1: INVEST_OTHER_IND_DETAILS | IH1: EMPLOYEE_DRUG_TEST_IND | II1: CONTRACTOR_DRUG_TEST_IND | IJ1: NUM_EMPLOYEES_TESTED | IK1: NUM_EMPLOYEES_FAILED | IL1: NUM_CONTRACTORS_TESTED | IM1: NUM_CONTRACTORS_FAILED | IN1: CAUSE | IO1: CAUSE_DETAILS | IP1: INTERNAL_EXTERNAL | IQ1: VISUAL_EXAM_RESULTS | IR1: VISUAL_EXAM_DETAILS | IS1: GALVANIC_CORROSION_IND | IT1: ATMOSPHERE_CORROSION_IND | IU1: STRAY_CURRENT_CORROSION_IND | IV1: MICROBIOLOGICAL_CORROSION_IND | IW1: SELECTIVE_SEAM_CORROSION_IND | IX1: OTHER_CORROSION_IND | IY1: CORROSION_TYPE_DETAILS | IZ1: STRAY_CURRENT_TYPE | JA1: STRAY_CURRENT_DETAILS | JB1: FIELD_EXAM_BASIS_IND | JC1: METALLURGICAL_BASIS_IND | JD1: OTHER_BASIS_IND | JE1: CORROSION_BASIS_DETAILS | JF1: UNDERGROUND_LOCATION | JG1: UNDER_CATHODIC_PROTECTION_IND | JH1: CATHODIC_PRO_START_YEAR | JI1: SHIELDING_EVIDENT | JJ1: CATHODIC_SURVEY_TYPE | JK1: CP_ANNUAL_SURVEY_IND | JL1: CLOSE_INTERVAL_SURVEY_IND | JM1: OTHER_CP_SURVEY_IND | JN1: OTHER_CP_SURVEY_DETAILS | JO1: CP_ANNUAL_SURVEY_YEAR | JP1: CLOSE_INTERVAL_SURVEY_YEAR | JQ1: OTHER_CP_SURVEY_YEAR | JR1: EXTERNALLY_COATED | JS1: PRIOR_DAMAGE | JT1: INT_VISUAL_EXAM_RESULTS | JU1: INT_VISUAL_EXAM_DETAILS | JV1: INT_CORROSIVE_COMMODITY_IND | JW1: INT_WATER_ACID_IND | JX1: INT_MICROBIOLOGICAL_IND | JY1: INT_EROSION_IND | JZ1: INT_OTHER_CORROSION_IND | KA1: INT_CORROSION_TYPE_DETAILS | KB1: INT_FIELD_EXAM_BASIS_IND | KC1: INT_METALLURGICAL_BASIS_IND | KD1: INT_OTHER_BASIS_IND | KE1: INT_CORROSION_BASIS_DETAILS | KF1: INT_LOW_POINT_PIPE_LOC_IND | KG1: INT_ELBOW_LOC_IND | KH1: INT_DROP_OUT_LOC_IND | KI1: INT_DEAD_LEG_LOC_IND | KJ1: INT_OTHER_LOC_IND | KK1: CORROSION_LOCATION_DETAILS | KL1: CORROSION_INHIBITORS | KM1: CORROSION_LINING | KN1: CLEANING_DEWATERING | KO1: CORROSION_COUPONS | KP1: NATURAL_FORCE_TYPE | KQ1: EARTH_SUBTYPE | KR1: HEAVY_RAINS_SUBTYPE | KS1: LIGHTNING_SUBTYPE | KT1: TEMPERATURE_SUBTYPE | KU1: NF_OTHER_DETAILS | KV1: NF_EXTREME_WEATHER_IND | KW1: NF_HURRICANE_IND | KX1: NF_TROPICAL_STORM_IND | KY1: NF_TORNADO_IND | KZ1: NF_OTHER_IND | LA1: NF_EXTREME_WEATHER_DETAILS | LB1: EX_PARTY_TYPE | LC1: PRIOR_NOTIFICATION_IND | LD1: ONE_CALL_SYSTEM_IND | LE1: EXCAVATOR_IND | LF1: CONTRACTOR_IND | LG1: LANDOWNER_IND | LH1: STATE_LAW_EXEMPT_IND | LI1: STATE_LAW_EXEMPT_TYPE | LJ1: STATE_LAW_EXEMPT_DETAIL | LK1: STATE_LAW_EXEMPT_AUTHORITY | LL1: STATE_LAW_EXEMPT_CRITERIA | LM1: NOTIFY_CGA_DIRT | LN1: PUBLIC_ROW_IND | LO1: PUBLIC_SUBTYPE | LP1: PRIVATE_ROW_IND | LQ1: PRIVATE_SUBTYPE | LR1: PIPELINE_EASEMENT_ROW_IND | LS1: POWER_TRANSMISSION_ROW_IND | LT1: RAILROAD_ROW_IND | LU1: PUBLIC_UTIL_EASEMENT_ROW_IND | LV1: FEDERAL_LAND_ROW_IND | LW1: UNKNOWN_ROW_IND | LX1: JOINT_TRENCH_IND | LY1: CROSS_BORE_IND | LZ1: DEPTH_OF_GRADE | MA1: DEPTH_OF_GRADE_DETAIL | MB1: EXCAVATOR_TYPE | MC1: EXCAVATOR_EQUIPMENT | MD1: WORK_PERFORMED | ME1: ONE_CALL_NOTIFIED_IND | MF1: ONE_CALL_TICKET_NUM | MG1: ONE_CALL_CENTER_NAME | MH1: WHITE_LINED_IND | MI1: LOCATOR_TYPE | MJ1: VISIBLE_MARKS | MK1: SERVICE_INTERRUPTION | ML1: SERVICE_INTERRUPTION_HOURS | MM1: ROOT_CAUSE_CATEGORY | MN1: ROOT_CAUSE_TYPE | MO1: ROOT_CAUSE_TYPE_OTHER | MP1: OUTSIDE_FORCE_TYPE | MQ1: VEHICLE_SUBTYPE | MR1: OSF_HURRICANE_IND | MS1: OSF_TROPICAL_STORM_IND | MT1: OSF_TORNADO_IND | MU1: OSF_HEAVY_RAINS_IND | MV1: OSF_OTHER_WEATHER_IND | MW1: OSF_OTHER_WEATHER_DETAILS | MX1: INTENTIONAL_SUBTYPE | MY1: INTENTIONAL_DETAILS | MZ1: OSF_OTHER_DETAILS | NA1: DRIVER_ISSUED_CITATION_IND | NB1: CITATION_SPEED_IND | NC1: CITATION_RECKLESS_IND | ND1: CITATION_DUI_IND | NE1: CITATION_OTHER_IND | NF1: CITATION_OTHER_DETAIL | NG1: DRIVER_IN_CONTROL_IND | NH1: ESTIMATED_SPEED | NI1: ESTIMATED_SPEED_UNKNOWN_IND | NJ1: VEHICLE_TYPE | NK1: VEHICLE_TRAVEL_FROM | NL1: VEHICLE_TRAVEL_DISTANCE_FT | NM1: PROTECTIONS_INSTALLED_IND | NN1: PROTECTION_BOLLARDS_POST_IND | NO1: PROTECTION_BARRICADES_IND | NP1: PROTECTION_GUARD_RAILS_IND | NQ1: PROTECTION_OTHER_IND | NR1: PROTECTION_OTHER_DETAIL | NS1: PWJF_FAILURE_TYPE | NT1: FIELD_EXAM_IND | NU1: METALLURGICAL_IND | NV1: OTHER_ANALYSIS_IND | NW1: OTHER_ANALYSIS_DETAILS | NX1: STILL_UNDER_INVEST_IND | NY1: FATIGUE_VIBR_RELATED | NZ1: FAILURE_SUBTYPE | OA1: FATIGUE_VIBR_RELATED_OTHER | OB1: MECHANICAL_STRESS | OC1: OTHER_FACTOR | OD1: OTHER_FACTOR_DETAILS | OE1: STRESS_SUBTYPE | OF1: STRESS_DETAILS | OG1: ADDITIONAL_DENT_IND | OH1: ADDITIONAL_GOUGE_IND | OI1: ADDITIONAL_PIPE_BEND_IND | OJ1: ADDITIONAL_ARC_BURN_IND | OK1: ADDITIONAL_CRACK_IND | OL1: ADDITIONAL_LACK_FUSION_IND | OM1: ADDITIONAL_LAMINATION_IND | ON1: ADDITIONAL_BUCKLE_IND | OO1: ADDITIONAL_WRINKLE_IND | OP1: PWF_ADDITIONAL_MISALIGN_IND | OQ1: ADDITIONAL_BURNT_STEEL_IND | OR1: PWF_ADDITIONAL_OTHER_IND | OS1: ADDITIONAL_OTHER_DETAILS | OT1: POST_CONSTR_PRESSURE_TEST_VAL | OU1: EQ_FAILURE_TYPE | OV1: CONTROL_VALVE_IND | OW1: INSTRUMENTATION_IND | OX1: SCADA_IND | OY1: COMMUNICATIONS_IND | OZ1: BLOCK_VALVE_IND | PA1: CHECK_VALVE_IND | PB1: RELIEF_VALVE_IND | PC1: POWER_FAILURE_IND | PD1: STOPPLE_CONTROL_FITTING_IND | PE1: PRESSURE_REGULATOR_IND | PF1: ESD_SYSTEM_FAILURE_IND | PG1: OTHER_CONTROL_RELIEF_IND | PH1: OTHER_CONTROL_RELIEF_DETAILS | PI1: OTHER_COMPRESSOR_IND | PJ1: OTHER_COMPRESSOR_DETAILS | PK1: OTHER_STRIPPED_IND | PL1: OTHER_STRIPPED_DETAILS | PM1: OTHER_NON_THREADED_IND | PN1: OTHER_NON_THREADED_DETAILS | PO1: EQ_FAILURE_DETAILS | PP1: ADDITIONAL_VIBRATION_IND | PQ1: ADDITIONAL_OVERPRESSURE_IND | PR1: ADDITIONAL_SUPPORT_IND | PS1: ADDITIONAL_DEFECT_IND | PT1: ADDITIONAL_ELECTRICITY_IND | PU1: ADDITIONAL_INSTALLATION_IND | PV1: ADDITIONAL_IMPROPER_MNTNCE_IND | PW1: ADDITIONAL_MISMATCH_IND | PX1: ADDITIONAL_DISSIMILAR_IND | PY1: ADDITIONAL_BREAKDOWN_IND | PZ1: ADDITIONAL_VALVE_IND | QA1: ADDITIONAL_ALARM_IND | QB1: EQ_ADDITIONAL_MISALIGN_IND | QC1: EQ_ADDITIONAL_THERMAL_IND | QD1: ADDITIONAL_EROSION_WEAR_IND | QE1: EQ_ADDITIONAL_OTHER_IND | QF1: EQ_ADDITIONAL_OTHER_DETAILS | QG1: OPERATION_TYPE | QH1: OVERFLOW_OTHER_IND | QI1: OVERFLOW_OTHER_DETAILS | QJ1: OPERATION_DETAILS | QK1: RELATED_INADEQUATE_PROC_IND | QL1: RELATED_NO_PROC_IND | QM1: RELATED_FAILURE_FOLLOW_IND | QN1: RELATED_OTHER_IND | QO1: OPERATION_RELATED_DETAILS | QP1: CATEGORY_TYPE | QQ1: OPERATOR_QUALIFICATION_IND | QR1: QUALIFIED_INDIVIDUALS | QS1: OTHER_TYPE | QT1: MISC_DETAILS | QU1: UNKNOWN_SUBTYPE | QV1: INCIDENT_UNKNOWN_COMMENTS | QW1: COLLECTED_DATA_IND | QX1: AXIAL_MAGNETIC_FLX_LKG_IND | QY1: CIR_TRN_WAVE_MGN_FLX_LKG_IND | QZ1: ULTRASONIC_IND | RA1: GEOMETRY_DEFORMATION_IND | RB1: EMAT_IND | RC1: CPCM_IND | RD1: OTHER_TOOL_TECH_IND | RE1: AXIAL_RECENT_YEAR | RF1: AXIAL_RCNT_PROPUL_METHOD | RG1: AXIAL_RCNT_ATTUNED_DETECT | RH1: AXIAL_RCNT_ATND_DTCT_DTLS | RI1: AXIAL_RCNT_ATND_DTCT_METAL | RJ1: AXIAL_RCNT_ATT_DT_METAL_DTLS | RK1: AXIAL_PREVIOUS_YEAR | RL1: AXIAL_PREV_PROPUL_METHOD | RM1: AXIAL_PREV_ATTUNED_DETECT | RN1: AXIAL_PREV_ATND_DTCT_DTLS | RO1: AXIAL_PREV_ATND_DTCT_METAL | RP1: AXIAL_PREV_ATT_DT_METAL_DTLS | RQ1: CIRC_WAVE_RECENT_YEAR | RR1: CIRC_WV_RCNT_PROPUL_METHOD | RS1: CIRC_WV_RCNT_RESOLUTION | RT1: CIRC_WV_RCNT_RESOLUTION_DTLS | RU1: CIRC_WV_PREVIOUS_YEAR | RV1: CIRC_WV_PREV_PROPUL_METHOD | RW1: CIRC_WV_PREV_RESOLUTION | RX1: CIRC_WV_PREV_RESOLUTION_DTLS | RY1: ULTRASONIC_RECENT_YEAR | RZ1: ULTRASONIC_RCNT_PROPUL_METHOD | SA1: ULTRASONIC_RCNT_ATTUNED | SB1: ULTRA_RCNT_ATTUNEDD_DTLS | SC1: UTRA_RCNT_ATT_METL_RESOLUTION | SD1: UTRA_RCNT_ATT_METL_RES_DTLS | SE1: ULTR_PREVIOUS_YEAR | SF1: ULTRA_PREV_PROPUL_METHOD | SG1: ULTRA_PREV_ATTUNED | SH1: ULTRA_PREV_ATTUNED_DTLS | SI1: UTRA_PREV_ATT_METL_RESOLUTION | SJ1: UTRA_PREV_ATT_METL_RES_DTLS | SK1: GEOMETRY_RECENT_YEAR | SL1: GEOMETRY_RCNT_PROPUL_METHOD | SM1: GEOMETRY_RCNT_RESOLUTION | SN1: GEOMETRY_RCNT_RESOLUTION_DTLS | SO1: GEOMETRT_RCNT_MEASUR_CUPS | SP1: GEOMETRY_PREVIOUS_YEAR | SQ1: GEOMETRY_PREV_PROPUL_METHOD | SR1: GEOMETRY_PREV_RESOLUTION | SS1: GEOMETRY_PREV_RESOLUTION_DTLS | ST1: GEOMETRT_PREV_MEASUR_CUPS | SU1: EMAT_RECENT_YEAR | SV1: EMAT_RCNT_PROPUL_METHOD | SW1: EMAT_PREVIOUS_YEAR | SX1: EMAT_PREV_PROPUL_METHOD | SY1: CPCM_RECENT_YEAR | SZ1: CPCM_RCNT_PROPUL_METHOD | TA1: CPCM_PREVIOUS_YEAR | TB1: CPCM_PREV_PROPUL_METHOD | TC1: OTHER_TOOL | TD1: OTHER_RECENT_YEAR | TE1: OTHER_RCNT_PROPUL_METHOD | TF1: OTHER_PREVIOUS_YEAR | TG1: OTHER_PREV_PROPUL_METHOD | TH1: INSP_COMPL_BEFORE_DAMAGE_IND | TI1: HAS_HYDRTST_CONDUC_BEFORE_IND | TJ1: HYDRTST_MOST_RCNT_YEAR | TK1: HYDRTST_MOST_RCNT_PRESSURE | TL1: DIRECT_ASMNT_CONDUCTED | TM1: DIRECT_ASMNT_AT_PNT_ACCDNT_YR | TN1: DIRECT_ASMNT_PNT_NOT_IDNTF_YR | TO1: ASMNT_ECDA_RCNT_YEAR | TP1: ASMNT_ICDA_RCNT_YEAR | TQ1: ASMNT_SCCDA_RCNT_YEAR | TR1: ASMNT_CONFIRMATORY_RCNT_YEAR | TS1: ASMNT_OTHER_TYPE | TT1: ASMNT_OTHER_RCNT_YEAR | TU1: ASMNT_ECDA_RCNT_IND | TV1: ASMNT_ICDA_RCNT_IND | TW1: ASMNT_SCCDA_RCNT_IND | TX1: ASMNT_CONFIRMATORY_RCNT_IND | TY1: ASMNT_OTHER_RCNT_IND | TZ1: NON_DESTRUCTIVE_EXAM_IND | UA1: EXM_RADIOGRAPHY_RCNT_YEAR | UB1: EXM_WAVE_ULTRASONIC_RCNT_YEAR | UC1: EXM_HANDL_ULTRASONIC_RCNT_YEAR | UD1: EXM_WET_MGNT_PARTCL_RCNT_YEAR | UE1: EXM_DRY_MGNT_PARTCL_RCNT_YEAR | UF1: EXM_OTHER_TYPE | UG1: EXM_OTHER_RCNT_YEAR | UH1: EXM_RADIOGRAPHY_RCNT_IND | UI1: EXM_WAVE_ULTRASONIC_RCNT_IND | UJ1: EXM_HANDL_ULTRASONIC_RCNT_IND | UK1: EXM_WET_MGNT_PARTCL_RCNT_IND | UL1: EXM_DRY_MGNT_PARTCL_RCNT_IND | UM1: EXM_OTHER_RCNT_IND | UN1: EXTRNL_COR_GALVANIC_IND | UO1: EXTRNL_COR_ATMOSPHERIC_IND | UP1: EXTRNL_COR_STRAY_CURRENT_IND | UQ1: EXTRNL_COR_MICROBIOLOGIC_IND | UR1: EXTRNL_COR_SELECTIVE_SEAM_IND | US1: INTRNL_COR_CORROSIVE_CMDTY_IND | UT1: INTRNL_COR_WTR_DRPOUT_ACID_IND | UU1: INTRNL_COR_MICROBIOLOGIC_IND | UV1: INTRNL_COR_EROSION_IND | UW1: NF_EARTH_MOVEMENT_IND | UX1: NF_HEAVY_RAINS_IND | UY1: NF_LIGHTNING_IND | UZ1: NF_TEMPERATURE_IND | VA1: NF_HIGH_WINDS_IND | VB1: NF_VEGITATION_ROOT_IND | VC1: EXCVTN_DMG_OPERATOR_IND | VD1: EXCVTN_DMG_OP_CONTRACTOR_IND | VE1: EXCVTN_DMG_THIRD_PARTY_IND | VF1: EXCVTN_DMG_PREVIOUS_DAMAGE_IND | VG1: OSF_NEARBY_INDUSTRIAL_IND | VH1: OSF_VEHICLE_IND | VI1: OSF_BOAT_IND | VJ1: OSF_OTHER_MARITIME_IND | VK1: OSF_ELECTRICAL_ARCING_IND | VL1: OSF_PREVIOUS_MECHANICAL_IND | VM1: OSF_INTENTIONAL_IND | VN1: OSF_OTHER_UNDERGROUND_IND | VO1: PWF_DESIGN_IND | VP1: PWF_CONSTRUCTION_IND | VQ1: PWF_INSTALLATION_IND | VR1: PWF_FABRICATION_IND | VS1: PWF_MANUFACTURING_IND | VT1: PWF_ENV_STRESS_CORROSION_IND | VU1: PWF_ENV_SULFIDE_STRESS_IND | VV1: PWF_ENV_HYDROGEN_STRESS_IND | VW1: PWF_ENV_HARD_SPOT_IND | VX1: EQF_CONTROL_RELEAF_IND | VY1: EQF_COMPRESSOR_IND | VZ1: EQF_THREADED_COUPLING_IND | WA1: EQF_NON_THREADED_IND | WB1: EQF_DEFECTIVE_FITTING_IND | WC1: EQF_EQUIPMENT_BODY_IND | WD1: IO_DAMAGE_BY_OPERATOR_IND | WE1: IO_VALVE_POSITION_IND | WF1: IO_EQUIPMENT_OVERPRESSURE_IND | WG1: IO_NOT_INSTALLED_PROPERLY_IND | WH1: IO_WRONG_EQUIPMENT_IND | WI1: IO_INADEQUATE_PROCEDURE_IND | WJ1: IO_NO_PROCEDURE_IND | WK1: IO_FOLLOW_PROCEDURE_IND | WL1: PREPARER_NAME | WM1: PREPARER_TITLE | WN1: PREPARER_EMAIL | WO1: PREPARER_TELEPHONE | WP1: PREPARER_FAX | WQ1: LOCAL_CONTACT_NAME | WR1: LOCAL_CONTACT_EMAIL | WS1: LOCAL_CONTACT_TELEPHONE | WT1: AUTHORIZER_NAME | WU1: AUTHORIZER_TITLE | WV1: AUTHORIZER_TELEPHONE | WW1: AUTHORIZER_EMAIL | WX1: NARRATIVE
A2: 0 | B2: 45832 | C2: 2025 | D2: 20250073 | E2: 41071 | F2: ORIGINAL | G2: 32099 | H2: ENERGY TRANSFER COMPANY | I2: 1300 MAIN STREET | J2: HOUSTON | K2: TX | L2: 77002 | M2: 45805.849 | N2: CENTRAL | O2: NO | P2: 31.275848 | Q2: -101.69314 | R2: 1432147 | S2: 45806.577 | T2: 1432269 | U2: NATURAL GAS | W2: 39 | X2: 0 | Y2: 0 | Z2: NO | AF2: 0 | AG2: NO | AM2: 0 | AN2: NORMAL OPERATION, INCLUDES PAUSES DURING MAINTENANCE | AO2: YES | AQ2: 45805.849 | AR2: 45806.115 | AT2: YES | AU2: OPERATOR | AV2: 45805.854 | AW2: YES | AX2: 45805.849 | AY2: LOCAL/STATE/FEDERAL EMERGENCY RESPONDER | BA2: 39 | BB2: NO | BI2: 0 | BJ2: 45805.849 | BK2: 45805.861 | BL2: 45805.861 | BM2: ONSHORE | BN2: TX | BO2: 76932 | BP2: Not Within a Municipality | BQ2: REAGAN | BR2: NOT APPLICABLE | BT2: GARRISON DRAW COMPRESSOR STATION | BU2: 7406595 - SEQUITUR TO GARISON | BV2: NO | BW2: OPERATOR-CONTROLLED PROPERTY | BX2: ABOVEGROUND | BY2: TYPICAL ABOVEGROUND FACILITY PIPING OR APPURTENANCE | CC2: NO | CZ2: INTRASTATE | DA2: ONSHORE COMPRESSOR STATION EQUIPMENT AND PIPING | DB2: COMPRESSOR | EO2: 2024 | EP2: 2018 | EQ2: CARBON STEEL | ES2: LEAK | EV2: SEAL OR PACKING | FC2: CLASS 1 LOCATION | FD2: NO | FF2: 211 | FH2: NO | FI2: NO | FL2: NO | FO2: 0 | FP2: 139 | FQ2: 0 | FR2: 146000 | FS2: 5000 | FT2: 0 | FV2: 3.57 | FW2: 151139 | FX2: 0 | FY2: 0 | FZ2: 0 | GA2: 0 | GB2: NO | GF2: 30 | GG2: 3900 | GH2: 1440 | GI2: 192.619(A)(4) | GK2: 44285 | GL2: NO | GM2: PRESSURE DID NOT EXCEED MAOP | GN2: NO | GQ2: NO | HK2: TYPE C GATHERING | HL2: YES | HM2: YES | HN2: YES | HO2: YES | HP2: NO | HQ2: SCADA-BASED INFORMATION (SUCH AS ALARM(S), ALERT(S), EVENT(S), AND/OR VOLUME OR PACK CALCULATIONS) | HT2: NO, THE FACILITY WAS NOT MONITORED BY A CONTROLLER(S) AT THE TIME OF THE INCIDENT | IH2: NO | II2: NO | IN2: OTHER INCIDENT CAUSE | IO2: UNKNOWN | QS2: UNKNOWN | QU2: STILL UNDER INVESTIGATION, CAUSE OF INCIDENT TO BE DETERMINED* (*SUPPLEMENTAL REPORT REQUIRED) | WL2: TOBY PITTMAN | WN2: toby.pittman@energytransfer.com | WO2: 432-265-6810 | WQ2: TOBY PITTMAN | WR2: toby.pittman@energytransfer.com | WS2: 4322656810 | WT2: JUSTIN DAVIDSON | WV2: 7139895231 | WW2: justin.davidson@energytransfer.com | WX2: ON MAY 28, 2025, AT 8:22 P.M. AN ON-CALL PIPELINE TECH WITH ENERGY TRANSFER COMPANY (ETC) RECEIVED AN ALARM LOLO COMPRESSOR OIL INDICATING THAT THE COMPRESSOR, GARRISON DRAW UNIT 5 # 2777 USA COMPRESSOR WAS SHUT DOWN. AT ABOUT 8:30 P.M. WHILE ENROUTE TO THE COMPRESSOR STATION THE TECH WITNESSED A FIRE THAT WAS POSSIBLY LOCATED AT THE GARRISON DRAW COMPRESSOR STATION. THE TECH THEN NOTIFIED THE OPERATIONS SUPERVISOR, WHO THEN NOTIFIED THE FIRE DEPARTMENT. THEN THE TECH BEGAN SHUTTING IN METER RUN VALVES SENDING NATURAL GAS TO THE COMPRESSOR STATION. AT 8:40 P.M. THE PIPELINE TECH ARRIVED AT THE COMPRESSOR STATION AND CONFIRMED THE FIRE WAS ON ETC'S GARRISON DRAW UNIT 5. THE FIRE DEPARTMENT WAS ALREADY ON SCENE AT THAT TIME. THE PIPELINE TECH THEN ISOLATED GARRISON DRAW. THE FIRE WAS OUT AT 9:30 P.M. ON MAY 29, 2025, THE STATION WAS RETURNED TO SERVICE WITHOUT UNIT 5 AT 2:49 A.M. NRC NOTIFICATION WAS MADE AT 1:51 P.M. MAY 29, 2025. THE CAUSE OF THE FIRE IS STILL UNDER INVESTIGATION.
A3: 1 | B3: 45832 | C3: 2025 | D3: 20250072 | E3: 41069 | F3: ORIGINAL | G3: 39368 | H3: CRESTWOOD MIDSTREAM PARTNERS LP | I3: 1300 MAIN STREET | J3: HOUSTON | K3: TX | L3: 77002 | M3: 45802.326 | N3: CENTRAL | O3: NO | P3: 31.84378 | Q3: -103.75784 | R3: 1432147 | S3: 45802.61 | T3: 1432269 | U3: NATURAL GAS | W3: 15 | X3: 0 | Y3: 0 | Z3: NO | AF3: 0 | AG3: NO | AM3: 0 | AN3: NORMAL OPERATION, INCLUDES PAUSES DURING MAINTENANCE | AO3: YES | AQ3: 45802.332 | AR3: 45804.383 | AT3: YES | AU3: OPERATOR | AV3: 45802.342 | AW3: YES | AX3: 45802.331 | AY3: LOCAL/STATE/FEDERAL EMERGENCY RESPONDER | BA3: 15 | BB3: NO | BI3: 0 | BJ3: 45802.331 | BK3: 45802.364 | BL3: 45802.331 | BM3: ONSHORE | BN3: TX | BO3: 79754 | BP3: Not Within a Municipality | BQ3: LOVING | BR3: NOT APPLICABLE | BT3: WEST SLASH COMPRESSOR STATION | BU3: TX5052G BRANCH 55-9 | BV3: NO | BW3: OPERATOR-CONTROLLED PROPERTY | BX3: ABOVEGROUND | BY3: TYPICAL ABOVEGROUND FACILITY PIPING OR APPURTENANCE | CC3: NO | CZ3: INTRASTATE | DA3: ONSHORE COMPRESSOR STATION EQUIPMENT AND PIPING | DB3: COMPRESSOR | EO3: 2024 | EP3: 2018 | EQ3: CARBON STEEL | ES3: OTHER | FB3: UNDER INVESTIGATION | FC3: CLASS 1 LOCATION | FD3: NO | FF3: 211 | FH3: NO | FI3: NO | FL3: NO | FO3: 0 | FP3: 56 | FQ3: 0 | FR3: 146000 | FS3: 5000 | FT3: 0 | FV3: 3.71 | FW3: 151056 | FX3: 2 | FY3: 0 | FZ3: 0 | GA3: 0 | GB3: NO | GF3: 88 | GG3: 0 | GH3: 720 | GI3: 192.619(A)(4) | GK3: 45607 | GL3: NO | GM3: PRESSURE DID NOT EXCEED MAOP | GN3: NO | GQ3: NO | HK3: TYPE C GATHERING | HL3: YES | HM3: YES | HN3: YES | HO3: NO | HP3: NO | HQ3: LOCAL OPERATING PERSONNEL, INCLUDING CONTRACTORS | HS3: OPERATOR EMPLOYEE | HT3: NO, THE FACILITY WAS NOT MONITORED BY A CONTROLLER(S) AT THE TIME OF THE INCIDENT | IH3: NO | II3: YES | IL3: 1 | IM3: 0 | IN3: OTHER INCIDENT CAUSE | IO3: UNKNOWN | QS3: UNKNOWN | QU3: STILL UNDER INVESTIGATION, CAUSE OF INCIDENT TO BE DETERMINED* (*SUPPLEMENTAL REPORT REQUIRED) | WL3: TOBY PITTMAN | WN3: toby.pittman@energytransfer.com | WO3: 432-265-6810 | WQ3: TOBY PITTMAN | WR3: toby.pittman@energytransfer.com | WS3: 4322656810 | WT3: JUSTIN DAVIDSON | WV3: 7139895231 | WW3: justin.davidson@energytransfer.com | WX3: ON MAY 25, 2025, AT 7:57 A.M., WHILE MAINTENANCE WAS BEING PERFORMED BY AN ENERGY TRANSFER COMPANY (ETC) EMPLOYEE AND A CONTRACT EMPLOYEE, THE WEST SLASH UNIT 2 COMPRESSOR, CAUGHT FIRE. THE ETC EMPLOYEE NOTIFIED THE OPERATIONS MANAGER WHO THEN NOTIFIED EMERGENCY SERVICES. THE EMPLOYEE AND CONTRACT EMPLOYEE ACTIVATED THE EMERGENCY SHUT DOWN SYSTEM (ESD) SUCCESSFULLY SHUTTING DOWN THE COMPRESSOR STATION. BOTH THE ETC EMPLOYEE AND CONTRACT EMPLOYEE WERE INJURED WHEN THE FIRE IGNITED. WHEN EMERGENCY SERVICES ARRIVED AT THE LOCATION THE TWO INJURED RECEIVED MEDICAL ATTENTION AND THE FIRE WAS EXTINGUISHED. DUE TO THE EXTENT OF THE FIRE TO THE COMPRESSOR, THE COST OF REPAIRS ARE ESTIMATED TO EXCEED $145,400. THE CAUSE OF THE FIRE IS STILL UNDER INVESTIGATION.
A4: 3 | B4: 45812 | C4: 2025 | D4: 20250066 | E4: 40988 | F4: ORIGINAL FINAL | G4: 18152 | H4: SEA ROBIN PIPELINE CO | I4: 1300 MAIN STREET | J4: HOUSTON | K4: TX | L4: 77002 | M4: 45794.604 | N4: CENTRAL | O4: YES | P4: 28.246468 | Q4: -91.70387 | R4: 1421397 | S4: 45794.633 | T4: 1431515, 1431997 | U4: NATURAL GAS | W4: 1587069 | X4: 0 | Y4: 0 | Z4: NO | AF4: 0 | AG4: NO | AM4: 0 | AN4: NORMAL OPERATION, INCLUDES PAUSES DURING MAINTENANCE | AO4: YES | AQ4: 45794.609 | AR4: 45801.615 | AT4: YES | AU4: OPERATOR | AV4: 45794.633 | AW4: NO | BC4: VALVE CLOSURE | BE4: 45794.512 | BF4: VALVE CLOSURE | BH4: 45794.609 | BI4: 0 | BJ4: 45800.611 | BK4: 45794.512 | BL4: 45800.611 | BM4: OFFSHORE | BT4: SEA ROBIN | BU4: LINE 716-10-1 | CP4: 260 | CQ4: ON THE OUTER CONTINENTAL SHELF (OCS) | CV4: OCS-GULF OF AMERICA | CW4: EUGENE ISLAND | CX4: 330 | CY4: BELOW WATER, PIPE BURIED OR JETTED BELOW SEABED | CZ4: INTERSTATE | DA4: OFFSHORE PIPELINE, INCLUDING RISER AND RISER BEND | DB4: PIPE | DC4: PIPE BODY | DD4: 8.625 | DE4: NO | DF4: 0.41 | DG4: 24000 | DH4: API 5L X52 | DI4: OTHER | DJ4: UNKNOWN | DK4: UNKNOWN | DL4: OTHER | DM4: MASTEC & CONCRETE | DN4: YES | EO4: 1973 | EP4: 1973 | EQ4: CARBON STEEL | ES4: LEAK | EV4: PINHOLE | FC4: CLASS 1 LOCATION | FD4: NO | FF4: 215 | FH4: NO | FI4: NO | FL4: NO | FO4: 0 | FP4: 5523000 | FQ4: 0 | FR4: 350000 | FS4: 35000 | FT4: 0 | FV4: 3.48 | FW4: 5908000 | FX4: 0 | FY4: 0 | FZ4: 0 | GA4: 0 | GB4: NO | GF4: 900 | GG4: 3000 | GH4: 1306 | GI4: 192.619(A)(1) | GK4: 28126 | GL4: NO | GM4: PRESSURE DID NOT EXCEED MAOP | GN4: NO | GQ4: NO | GS4: MANUAL | GT4: MANUAL | GU4: 31680 | GV4: NO | GY4: YES | HD4: YES | HG4: YES | HK4: TRANSMISSION SYSTEM | HL4: YES | HM4: YES | HN4: YES | HO4: NO | HP4: NO | HQ4: OTHER | HR4: NOTIFIED BY PRODUCER | HT4: NO, THE OPERATOR DID NOT FIND THAT AN INVESTIGATION OF THE CONTROLLER(S) ACTIONS OR CONTROL ROOM ISSUES WAS NECESSARY DUE TO: (PROVIDE AN EXPLANATION FOR WHY THE OPERATOR DID NOT INVESTIGATE) | HU4: LEAK WAS TOO SMALL FOR SCADA TO DETECT | IH4: NO | II4: NO | IN4: CORROSION FAILURE | IO4: INTERNAL CORROSION | IP4: INTERNAL CORROSION | JT4: NOT CUT OPEN | JV4: YES | KB4: YES | KF4: YES | KL4: NO | KM4: NO | KN4: NO | KO4: NOT APPLICABLE - NOT MAINLINE PIPE | QW4: NO | TI4: NO | TL4: NO | TZ4: NO | WL4: PEGGY WEST | WM4: MANAGER DOT COMPLIANCE | WN4: peggy.west@energytransfer.com | WO4: 4093823918 | WT4: PEGGY WEST | WU4: MANAGER DOT COMPLIANCE | WV4: 4093823918 | WW4: peggy.west@energytransfer.com | WX4: AT APPROXIMATELY 1212 ON 05/17/25, OPERATIONS RECEIVED A NOTIFICATION FROM A 3RD PARTY REPORTING BUBBLES IN THE AREA NEAR THE SEA ROBIN 716-10-1 LATERAL IN EUGENE ISLAND 330 (EI 330). AN OVERFLIGHT WAS CONDUCTED TO VERIFY THE LOCATION OF THE BUBBLES AND WAS CONFIRMED AT APPROXIMATELY 1430 ON 05/17/25. NRC WAS CALLED REPORTING THE BUBBLES IN EI 331 (NRC#1431397, 48HR UPDATE#1431515). THE PIPELINE WAS ISOLATED ON 05/17/25 AT 1437. OVERFLIGHTS WERE CONDUCTED DAILY TO MONITOR THE AREA FOR ANY CHANGES AS WEATHER PERMITTED. DUE TO DSV AVAILABILITY, THE REPAIR CONTRACTOR WAS NOT ABLE TO DEPLOY UNTIL 5/11/25. THE LEAK WAS LOCATED AND A CLAMP WAS INSTALLED ON 5/24/25 AT 0650. THE PIPELINE WAS RETURNED TO SERVICE AT APPROXIMATELY 1346 ON 05/24/25. THE 48HR NRC NOTIFICATION WAS UPDATED ON 05/23/25 AT 1440 TO REFLECT THE CHANGE FROM UNKNOWN OWNER TO SEA ROBIN PIPELINE. (#1431997)
A5: 7 | B5: 45823 | C5: 2025 | D5: 20250070 | E5: 41024 | F5: ORIGINAL | G5: 32099 | H5: ENERGY TRANSFER COMPANY | I5: 1300 MAIN STREET | J5: HOUSTON | K5: TX | L5: 77002 | M5: 45786.812 | N5: CENTRAL | O5: YES | P5: 32.01374 | Q5: -100.76041 | R5: 1431278 | S5: 45793.542 | T5: 1431410 | U5: NATURAL GAS | W5: 192 | X5: 0 | Y5: 0 | Z5: NO | AF5: 0 | AG5: NO | AM5: 0 | AN5: NORMAL OPERATION, INCLUDES PAUSES DURING MAINTENANCE | AO5: YES | AQ5: 45786.812 | AS5: YES | AT5: NO | AW5: NO | BC5: VALVE CLOSURE | BE5: 45786.812 | BF5: VALVE CLOSURE | BH5: 45786.84 | BI5: 0 | BJ5: 45786.812 | BK5: 45786.812 | BL5: 45793.521 | BM5: ONSHORE | BN5: TX | BO5: 76949 | BP5: SILVER | BQ5: COKE | BR5: SURVEY STATION NO. | BS5: 49+96.5 | BT5: PERKINS 10'' HP TO FT CHADBOURNE | BU5: 210000 | BV5: NO | BW5: PIPELINE RIGHT-OF-WAY | BX5: UNDERGROUND | BY5: UNDER SOIL | CA5: 24 | CB5: YES | CC5: NO | CZ5: INTRASTATE | DA5: ONSHORE PIPELINE, INCLUDING VALVE SITES | DB5: PIPE | DC5: PIPE BODY | DD5: 10.75 | DE5: NO | DF5: 0.365 | DG5: 24000 | DH5: UNKNOWN | DI5: LONGITUDINAL ERW - UNKNOWN FREQUENCY | DK5: UNKNOWN | DL5: COAL TAR | DN5: UNKNOWN | EO5: 1965 | EP5: UNKNOWN | EQ5: CARBON STEEL | ES5: RUPTURE | EX5: CIRCUMFERENTIAL | EZ5: 10.8 | FA5: 10.8 | FC5: CLASS 1 LOCATION | FD5: NO | FF5: 198 | FH5: NO | FI5: NO | FL5: NO | FO5: 0 | FP5: 609 | FQ5: 0 | FR5: 236000 | FS5: 1000 | FT5: 0 | FV5: 3.17 | FW5: 237609 | FX5: 0 | FY5: 0 | FZ5: 0 | GA5: 0 | GB5: NO | GF5: 245 | GG5: 538 | GH5: 1440 | GI5: 192.619(A)(1) | GK5: 23743 | GL5: NO | GM5: PRESSURE DID NOT EXCEED MAOP | GN5: NO | GQ5: NO | GS5: MANUAL | GT5: MANUAL | GU5: 11299 | GV5: YES | HD5: NO | HK5: TYPE C GATHERING | HL5: NO | HQ5: LOCAL OPERATING PERSONNEL, INCLUDING CONTRACTORS | HS5: OPERATOR EMPLOYEE | HT5: NO, THE FACILITY WAS NOT MONITORED BY A CONTROLLER(S) AT THE TIME OF THE INCIDENT | IH5: NO | II5: NO | IN5: OTHER INCIDENT CAUSE | IO5: UNKNOWN | QS5: UNKNOWN | QU5: STILL UNDER INVESTIGATION, CAUSE OF INCIDENT TO BE DETERMINED* (*SUPPLEMENTAL REPORT REQUIRED) | WL5: CHRIS PALAFOX | WM5: SR. SPECIALIST DOT COMPLIANCE | WN5: christopher.palafox@energytransfer.com | WO5: 3259333577 | WT5: JUSTIN DAVIDSON | WU5: MANAGER DOT COMPLIANCE | WV5: 7139895231 | WW5: justin.davidson@energytransfer.com | WX5: ON MAY 9, 2025, AN INCIDENT OCCURRED ON THE 210000 - PERKINS 10" HP TO FT CHADBOURNE, 6.14 MILES SOUTHWEST OF SILVER, TEXAS IN COKE COUNTY. AT APPROXIMATELY 1930 THE LINE HAD A RELEASE. IT WAS DETERMINED TO BE A RUPTURE THAT OCCURRED DURING ROUTINE MAINTENANCE PIGGING OPERATIONS. ON MAY 16, 2025, AT 1230, IT WAS DETERMINED THE REPAIRS WOULD EXCEED THE $145,400.00 REPORTABLE DOLLAR CRITERIA AND THE NRC AND THE TXRRC WERE NOTIFIED. THE LINE SEPARATION IS STILL UNDER INVESTIGATION AND THE AFFECTED SECTION OF THE PIPE HAS BEEN SENT TO THE LAB FOR ANALYSIS. A SUPPLEMENTAL REPORT WILL BE SUBMITTED WHEN THE LAB ANALYSIS AND INVESTIGATION IS COMPLETE.
A6: 21 | B6: 45785 | C6: 2025 | D6: 20250049 | E6: 40859 | F6: ORIGINAL | G6: 19730 | H6: TRUNKLINE GAS CO | I6: 1300 MAIN STREET | J6: HOUSTON | K6: TX | L6: 77002 | M6: 45756.548 | N6: CENTRAL | O6: YES | P6: 30.59601 | Q6: -93.227044 | R6: 1428154 | S6: 45756.588 | T6: 1428308 | U6: NATURAL GAS | W6: 8620 | X6: 0 | Y6: 0 | Z6: NO | AF6: 0 | AG6: NO | AM6: 0 | AN6: NORMAL OPERATION, INCLUDES PAUSES DURING MAINTENANCE | AO6: YES | AQ6: 45756.548 | AR6: 45756.668 | AT6: YES | AU6: OPERATOR | AV6: 45756.562 | AW6: NO | BI6: 0 | BJ6: 45756.548 | BK6: 45756.548 | BL6: 45756.548 | BM6: ONSHORE | BN6: LA | BO6: 70652 | BP6: LONGVILLE | BQ6: BEAUREGARD | BR6: NOT APPLICABLE | BT6: LONGVILLE COMPRESSOR STATION | BU6: 100-3 36-INCH | BV6: NO | BW6: OPERATOR-CONTROLLED PROPERTY | BX6: ABOVEGROUND | BY6: TYPICAL ABOVEGROUND FACILITY PIPING OR APPURTENANCE | CC6: NO | CZ6: INTERSTATE | DA6: ONSHORE COMPRESSOR STATION EQUIPMENT AND PIPING | DB6: VALVE | EH6: MAINLINE | EI6: PLUG | EK6: NORDSTROM | EO6: UNKNOWN | EP6: UNKNOWN | EQ6: CARBON STEEL | ES6: LEAK | EV6: SEAL OR PACKING | FC6: CLASS 1 LOCATION | FD6: NO | FF6: 805 | FH6: NO | FI6: NO | FL6: NO | FO6: 0 | FP6: 32928 | FQ6: 0 | FR6: 0 | FS6: 0 | FT6: 0 | FV6: 3.82 | FW6: 32928 | FX6: 0 | FY6: 0 | FZ6: 0 | GA6: 0 | GB6: NO | GF6: 885 | GG6: 1259540 | GH6: 900 | GI6: 192.619(A)(1) | GK6: 39363 | GL6: NO | GM6: PRESSURE DID NOT EXCEED MAOP | GN6: NO | GQ6: NO | HK6: TRANSMISSION SYSTEM | HL6: YES | HM6: YES | HN6: YES | HO6: YES | HP6: YES | HQ6: LOCAL OPERATING PERSONNEL, INCLUDING CONTRACTORS | HS6: OPERATOR EMPLOYEE | HT6: YES, SPECIFY INVESTIGATION RESULT(S): (SELECT ALL THAT APPLY) | HZ6: YES | IH6: NO | II6: NO | IN6: EQUIPMENT FAILURE | IO6: MALFUNCTION OF CONTROL/RELIEF EQUIPMENT | OU6: MALFUNCTION OF CONTROL/RELIEF EQUIPMENT | OZ6: YES | QE6: YES | QF6: EQUIPMENT FAILURE STILL UNDER INVESTIGATION | WL6: PEGGY WEST | WM6: MANAGER DOT COMPLIANCE | WN6: peggy.west@energytransfer.com | WO6: 4092023088 | WT6: JUSTIN DAVIDSON | WU6: MANAGER DOT COMPLIANCE | WV6: 7139895231 | WW6: justin.davidson@energytransfer.com | WX6: ON 04/09/25 AT APPROXIMATELY 1309 PM, A VALVE CAP O-RING FAILED CAUSING THE ENGINE ROOM GAS DETECTION SYSTEM TO TRIGGER THE ESD SYSTEM. A 26'' PLUG VALVE WAS FOUND TO BE LEAKING BY AND ADDITIONAL VALVES WERE MANUALLY OPERATED TO ISOLATE THE STATION. UPON INVESTIGATION, IT WAS DETERMINED THE 26'' PLUG VALVE WAS FOUND IN THE CLOSED POSITION HOWEVER, THE VALVE DID NOT CLOSE ENTIRELY. THE VALVE WAS INSPECTED, GREASED, FUNCTION TESTED AND WAS STILL FOUND TO BE NOT FULLY ISOLATING. THE SECTION WAS ISOLATED AND TAKEN OUT OF SERVICE. VALVE WAS LOCKED OUT AND TAGGED OUT FOR FURTHER INVESTIGATION AND REPAIRS. THE REST OF THE STATION WAS PUT BACK IN SERVICE. NOTIFICATION WAS MADE TO THE NRC (#1428154) AT 1406 PM ON 04/09/25 AND THE 48 HOUR UPDATE (1428308) WAS MADE ON 04/11/25 AT 0908 AM.
A7: 24 | B7: 45785 | C7: 2025 | D7: 20250050 | E7: 40862 | F7: ORIGINAL | G7: 32099 | H7: ENERGY TRANSFER COMPANY | I7: 1300 MAIN STREET | J7: HOUSTON | K7: TX | L7: 77002 | M7: 45755.604 | N7: CENTRAL | O7: YES | P7: 28.83275 | Q7: -98.14965 | R7: 1428135 | S7: 45756.471 | T7: 1428310 | U7: NATURAL GAS | W7: 1800 | X7: 0 | Y7: 0 | Z7: NO | AF7: 0 | AG7: NO | AM7: 0 | AN7: NORMAL OPERATION, INCLUDES PAUSES DURING MAINTENANCE | AO7: YES | AQ7: 45755.625 | AR7: 45758.991 | AT7: YES | AU7: OPERATOR | AV7: 45755.617 | AW7: YES | AX7: 45755.604 | AY7: ALLOWED TO BURN OUT | BA7: 1800 | BB7: YES | BC7: VALVE CLOSURE | BE7: 45755.635 | BF7: VALVE CLOSURE | BH7: 45755.608 | BI7: 0 | BJ7: 45755.604 | BK7: 45755.604 | BL7: 45756.438 | BM7: ONSHORE | BN7: TX | BO7: 78113 | BP7: FALLS CITY | BQ7: ATASCOSA | BR7: NOT APPLICABLE | BT7: 88884002 DEHY TO COY CITY 10IN | BU7: 88884002 DEHY TO COY CITY 10IN | BV7: NO | BW7: OPERATOR-CONTROLLED PROPERTY | BX7: UNDERGROUND | BY7: UNDER SOIL | CA7: 48 | CB7: NO | CC7: NO | CZ7: INTRASTATE | DA7: ONSHORE PIPELINE, INCLUDING VALVE SITES | DB7: PIPE | DC7: PIPE SEAM | DD7: 10.75 | DF7: 0.25 | DG7: 52000 | DH7: API 5L PSL 2 | DI7: LONGITUDINAL ERW - HIGH FREQUENCY | DK7: UNKNOWN | DL7: ASPHALT | DN7: UNKNOWN | EO7: UNKNOWN | EP7: UNKNOWN | EQ7: CARBON STEEL | ES7: RUPTURE | EX7: LONGITUDINAL | EZ7: 213.6 | FA7: 33.7 | FC7: CLASS 1 LOCATION | FD7: NO | FF7: 251 | FH7: NO | FI7: NO | FL7: NO | FO7: 0 | FP7: 4500 | FQ7: 0 | FR7: 170000 | FS7: 4800 | FT7: 0 | FV7: 2.5 | FW7: 179300 | FX7: 0 | FY7: 0 | FZ7: 0 | GA7: 0 | GB7: NO | GF7: 900 | GG7: 1500 | GH7: 1024 | GI7: 192.619(A)(2) | GK7: 44490 | GL7: NO | GM7: PRESSURE DID NOT EXCEED MAOP | GN7: NO | GQ7: NO | GS7: MANUAL | GT7: MANUAL | GU7: 52915 | GV7: YES | HD7: YES | HG7: YES | HK7: TYPE C GATHERING | HL7: NO | HQ7: LOCAL OPERATING PERSONNEL, INCLUDING CONTRACTORS | HS7: OPERATOR EMPLOYEE | HT7: NO, THE FACILITY WAS NOT MONITORED BY A CONTROLLER(S) AT THE TIME OF THE INCIDENT | IH7: NO | II7: NO | IN7: OTHER INCIDENT CAUSE | IO7: UNKNOWN | QS7: UNKNOWN | QU7: STILL UNDER INVESTIGATION, CAUSE OF INCIDENT TO BE DETERMINED* (*SUPPLEMENTAL REPORT REQUIRED) | WL7: MIKE SMITH | WM7: SR. SPECIALIST DOT COMPLIANCE | WN7: mike.smith2@energytransfer.com | WO7: 8328944289 | WT7: JUSTIN DAVIDSON | WU7: MANAGER DOT COMPLIANCE | WV7: 7139895231 | WW7: justin.davidson@energytransfer.com | WX7: ON APRIL 8, 2025, ENERGY TRANSFER (ET) PERSONNEL DETECTED A FIRE WHILE ON ET SITE NEAR THE 97 DEHY TO COY CITY PIPELINE AT 14:30. OPERATIONS BEGAN TO TAKE PRECAUTIONARY MEASURES AND COMPLETELY ISOLATED THE LINE AT 15:15 AND THE FIRE WAS ALLOWED TO BURN OUT. ET PERSONNEL CONFIRMED DISCOVERY ON APRIL 9TH AT 10:30 AND DETERMINED THAT THE INCIDENT WOULD EXCEED THE COST REPORTING THRESHOLD. THE LINE HAS BEEN REPAIRED AND WAS RETURNED TO SERVICE AT 23:47 ON APRIL 11TH, 2025. THE CAUSE OF THE INCIDENT IS CURRENTLY UNKNOWN, AND THE INVESTIGATION IS UNDERWAY.
A8: 26 | B8: 45772 | C8: 2025 | D8: 20250044 | E8: 41049 | F8: SUPPLEMENTAL FINAL | G8: 32099 | H8: ENERGY TRANSFER COMPANY | I8: 1300 MAIN STREET | J8: HOUSTON | K8: TX | L8: 77002 | M8: 45743.499 | N8: CENTRAL | O8: YES | P8: 28.332579 | Q8: -99.611097 | R8: 1427041 | S8: 45743.842 | T8: 1427135 | U8: NATURAL GAS | W8: 22988 | X8: 799 | Y8: 0 | Z8: NO | AF8: 0 | AG8: NO | AM8: 0 | AN8: NORMAL OPERATION, INCLUDES PAUSES DURING MAINTENANCE | AO8: YES | AQ8: 45743.508 | AR8: 45746.05 | AT8: YES | AU8: OPERATOR | AV8: 45743.552 | AW8: NO | BC8: VALVE CLOSURE | BE8: 45743.508 | BF8: VALVE CLOSURE | BH8: 45743.503 | BI8: 15 | BJ8: 45743.502 | BK8: 45743.412 | BL8: 45743.808 | BM8: ONSHORE | BN8: TX | BO8: 78836 | BP8: CATARINA | BQ8: DIMMIT | BR8: NOT APPLICABLE | BT8: 20101161 RICH EAGLEFORD MAINLINE | BU8: 20101161 RICH EAGLEFORD MAINLINE | BV8: NO | BW8: OPERATOR-CONTROLLED PROPERTY | BX8: ABOVEGROUND | BY8: TYPICAL ABOVEGROUND FACILITY PIPING OR APPURTENANCE | CC8: NO | CZ8: INTRASTATE | DA8: ONSHORE PIPELINE, INCLUDING VALVE SITES | DB8: SCRAPER/PIG TRAP | EO8: 2012 | EP8: 2011 | EQ8: CARBON STEEL | ES8: OTHER | FB8: FROM OPENING OF BALL VALVE | FC8: CLASS 1 LOCATION | FD8: NO | FF8: 660 | FH8: NO | FI8: NO | FL8: NO | FO8: 12000 | FP8: 89193 | FQ8: 3100 | FR8: 873500 | FS8: 0 | FT8: 0 | FV8: 3.88 | FW8: 977793 | FX8: 0 | FY8: 0 | FZ8: 0 | GA8: 1 | GB8: NO | GF8: 1003 | GG8: 600000 | GH8: 1300 | GI8: 192.619(A)(2) | GK8: 40807 | GL8: NO | GM8: PRESSURE DID NOT EXCEED MAOP | GN8: NO | GQ8: NO | GS8: REMOTELY CONTROLLED | GT8: REMOTELY CONTROLLED | GU8: 550 | GV8: YES | HD8: NO | HK8: TYPE C GATHERING | HL8: YES | HM8: YES | HN8: YES | HO8: NO | HP8: NO | HQ8: LOCAL OPERATING PERSONNEL, INCLUDING CONTRACTORS | HS8: OPERATOR EMPLOYEE | HT8: NO, THE OPERATOR DID NOT FIND THAT AN INVESTIGATION OF THE CONTROLLER(S) ACTIONS OR CONTROL ROOM ISSUES WAS NECESSARY DUE TO: (PROVIDE AN EXPLANATION FOR WHY THE OPERATOR DID NOT INVESTIGATE) | HU8: CONTROLLER DID NOT CONTRIBUTE TO THE INCIDENT | IH8: NO | II8: NO | IN8: INCORRECT OPERATION | IO8: OTHER INCORRECT OPERATION | QG8: OTHER INCORRECT OPERATION | QJ8: FAILURE TO FOLLOW PROCEDURES | QM8: YES | QP8: ROUTINE MAINTENANCE | QQ8: YES | QR8: YES, THEY WERE QUALIFIED FOR THE TASK(S) | WL8: JOSEPH STOVER | WM8: SR. SPECIALIST DOT COMPLIANCE | WN8: joseph.stover@energytransfer.com | WO8: 8323241027 | WT8: JUSTIN DAVIDSON | WU8: MANAGER DOT COMPLIANCE | WV8: 7138820590 | WW8: justin.davidson@energytransfer.com | WX8: ON MARCH 27TH, 2025, 11:59 A.M., AN UNEXPECTED RELEASE OF NATURAL GAS WAS OBSERVED AT THE HOLLYWOOD AND VINE FACILITY. THE RELEASE CAME FROM THE LAUNCHER DOOR CLOSURE AND BLOWDOWN STACK OF THE LOADING BARREL. AN ETC EMPLOYEE WAS ONSITE AND WAS ABLE TO QUICKLY ENGAGE THE ASD SYSTEM ALLOWING THE SYSTEM TO BLOCK AND BLEED WITHIN FIVE MINUTES. DURING OUR INTERNAL INVESTIGATION IT WAS DETERMINED THAT THE EMPLOYEE LOADING THE SPHERE PIGS INTO THE LAUNCHER HAD FAILED TO SECURE THE PIG LAUNCHER DOOR CLOSURE ASSEMBLY WHICH RESULTED IN A GAS RELEASE DURING THE BARREL PURGING PROCESS.
A9: 31 | B9: 45763 | C9: 2025 | D9: 20250037 | E9: 40762 | F9: SUPPLEMENTAL FINAL | G9: 15105 | H9: PANHANDLE EASTERN PIPELINE CO | I9: 1300 MAIN STREET | J9: HOUSTON | K9: TX | L9: 77002 | M9: 45733.75 | N9: CENTRAL | O9: YES | P9: 38.798212 | Q9: -93.676357 | R9: 1426129 | S9: 45733.804 | T9: 1426260 | U9: NATURAL GAS | W9: 3037 | X9: 5793 | Y9: 0 | Z9: NO | AF9: 0 | AG9: NO | AM9: 0 | AN9: NORMAL OPERATION, INCLUDES PAUSES DURING MAINTENANCE | AO9: YES | AQ9: 45733.876 | AR9: 45738.64 | AT9: YES | AU9: OPERATOR | AV9: 45733.778 | AW9: NO | BC9: VALVE CLOSURE | BE9: 45733.803 | BF9: VALVE CLOSURE | BH9: 45733.8 | BI9: 0 | BJ9: 45733.769 | BK9: 45733.769 | BL9: 45733.769 | BM9: ONSHORE | BN9: MO | BO9: 64093 | BP9: WARRENSBURG | BQ9: JOHNSON | BT9: LOUISBURG 100 | BU9: LOUISBURG-41-04-001-1400 | BV9: NO | BW9: PIPELINE RIGHT-OF-WAY | BX9: UNDERGROUND | BY9: UNDER SOIL | CA9: 40 | CB9: NO | CC9: NO | CZ9: INTERSTATE | DA9: ONSHORE PIPELINE, INCLUDING VALVE SITES | DB9: WELD/FUSION, INCLUDING HEAT-AFFECTED ZONE | DD9: 22 | DF9: 0.312 | DG9: 30700 | DH9: EYS | DI9: LAP WELDED | DK9: NATIONAL TUBE SUPPLY COMPANY | DL9: COAL TAR | DN9: YES | DV9: PIPE GIRTH WELD | DX9: NO | EO9: 1931 | EP9: 1931 | EQ9: CARBON STEEL | ES9: LEAK | EV9: CRACK | FC9: CLASS 1 LOCATION | FD9: NO | FF9: 304 | FH9: NO | FI9: NO | FL9: NO | FO9: 1050 | FP9: 6912 | FQ9: 13184 | FR9: 55000 | FS9: 650 | FT9: 0 | FV9: 2.2758 | FW9: 76796 | FX9: 0 | FY9: 0 | FZ9: 0 | GA9: 0 | GB9: NO | GF9: 370 | GG9: 47000 | GH9: 400 | GI9: 192.619(A)(4) | GK9: 41778 | GL9: NO | GM9: PRESSURE DID NOT EXCEED MAOP | GN9: NO | GQ9: NO | GS9: MANUAL | GT9: MANUAL | GU9: 41676 | GV9: YES | HD9: YES | HG9: YES | HK9: TRANSMISSION SYSTEM | HL9: YES | HM9: YES | HN9: YES | HO9: NO | HP9: NO | HQ9: NOTIFICATION FROM PUBLIC | HT9: NO, THE OPERATOR DID NOT FIND THAT AN INVESTIGATION OF THE CONTROLLER(S) ACTIONS OR CONTROL ROOM ISSUES WAS NECESSARY DUE TO: (PROVIDE AN EXPLANATION FOR WHY THE OPERATOR DID NOT INVESTIGATE) | HU9: THE LINE WAS OPERATING APPROXIMATELY 30 PSIG BELOW MAOP AT THE TIME OF INCIDENT. | IH9: NO | II9: NO | IN9: MATERIAL FAILURE OF PIPE OR WELD | IO9: DESIGN-, CONSTRUCTION-, INSTALLATION-, OR FABRICATION-RELATED | NS9: DESIGN-, CONSTRUCTION-, INSTALLATION-, OR FABRICATION-RELATED | NT9: YES | OB9: YES | OK9: YES | OT9: 725 | QW9: YES | QX9: YES | RA9: YES | RE9: 2009 | RF9: FREE SWIMMING | RG9: METAL LOSS | RI9: HIGH RESOLUTION | RK9: 2001 | RL9: FREE SWIMMING | RM9: METAL LOSS | RO9: HIGH RESOLUTION | SK9: 2009 | SL9: FREE SWIMMING | SM9: HIGH RESOLUTION | SO9: NO CUPS | SP9: 2001 | SQ9: FREE SWIMMING | SR9: HIGH RESOLUTION | ST9: INSIDE ILI CUPS | TI9: YES | TJ9: 1953 | TK9: 725 | TL9: NO | TZ9: NO | VP9: YES | WL9: KORY TICE | WN9: kory.tice@energytransfer.com | WO9: 8066644029 | WQ9: KEVIN FERGUSON | WR9: kevin.ferguson@energytransfer.com | WS9: 9139061521 | WT9: SUSIE SJULIN | WV9: 4055575271 | WW9: susie.sjulin@energytransfer.com | WX9: AT APPROXIMATELY 18:16 ON 3/17/25, A LANDOWNER CALLED THE LOCAL REGULATORMAN ABOUT A HISSING SOUND NEAR ONE OF THE PANHANDLE EASTERN PIPELINES. THE REGULATORMAN CALLED THE OPERATIONS MANAGER AND WAS DISPATCHED TO THE SITE. THE OPERATIONS MANAGER THEN NOTIFIED GAS CONTROL OF THE POSSIBLE LEAK. THE REGULATORMAN ARRIVED ON SITE AT 18:28 AND CONFIRMED THE SOUND WAS IN FACT A LEAK. THE OPERATIONS MANAGER DISPATCHED EMPLOYEES TO THE UPSTREAM AND DOWNSTREAM BLOCK VALVES. DUE TO THE PROXIMITY TO A ROAD, THE REGULATORMAN CALLED 911 TO ASSIST WITH TRAFFIC CONTROL. THE BLOCK VALVES WERE CLOSED BY 19:17 AND THE LINE WAS BLOWN FLAT BY 21:01. THE LEAK WAS IDENTIFIED AS A CRACKED ACETYLENE WELD. THE WELD WAS CUT OUT AND NEW PIPE WAS INSTALLED. THE LINE WAS PURGED AND PLACED BACK IN SERVICE ON 3/22/25.
A10: 35 | B10: 45757 | C10: 2025 | D10: 20250036 | E10: 40741 | F10: ORIGINAL | G10: 32099 | H10: ENERGY TRANSFER COMPANY | I10: 1300 MAIN STREET | J10: HOUSTON | K10: TX | L10: 77002 | M10: 45723.403 | N10: CENTRAL | O10: NO | P10: 28.063611 | Q10: -99.596111 | R10: 1425566 | S10: 45727.595 | T10: 1425717 | U10: NATURAL GAS | W10: 45 | X10: 51.5 | Y10: 1 | Z10: NO | AF10: 0 | AG10: NO | AM10: 0 | AN10: NORMAL OPERATION, INCLUDES PAUSES DURING MAINTENANCE | AO10: YES | AQ10: 45723.489 | AS10: YES | AT10: NO | AW10: NO | BC10: VALVE CLOSURE | BE10: 45723.472 | BF10: VALVE CLOSURE | BH10: 45723.489 | BI10: 0 | BJ10: 45723.403 | BK10: 45723.417 | BL10: 45727.587 | BM10: ONSHORE | BN10: TX | BO10: 78836 | BP10: CATARINA | BQ10: WEBB | BR10: NOT APPLICABLE | BT10: GALVAN G13 LTS | BU10: GALVAN G13 LTS | BV10: NO | BW10: PIPELINE RIGHT-OF-WAY | BX10: UNDERGROUND | BY10: UNDER SOIL | CA10: 49 | CB10: NO | CC10: NO | CZ10: INTRASTATE | DA10: ONSHORE PIPELINE, INCLUDING VALVE SITES | DB10: PIPE | DC10: PIPE BODY | DD10: 12 | DE10: NO | DF10: 0.25 | DG10: 52000 | DH10: UNKNOWN | DI10: LONGITUDINAL ERW - HIGH FREQUENCY | DK10: UNKNOWN | DL10: EPOXY | DN10: NO | EO10: 2012 | EP10: UNKNOWN | EQ10: CARBON STEEL | ES10: LEAK | EV10: PINHOLE | FC10: CLASS 1 LOCATION | FD10: NO | FF10: 660 | FH10: NO | FI10: NO | FL10: NO | FO10: 10000 | FP10: 198 | FQ10: 226 | FR10: 144500 | FS10: 0 | FT10: 0 | FV10: 4.39 | FW10: 154924 | FX10: 0 | FY10: 0 | FZ10: 0 | GA10: 0 | GB10: NO | GF10: 60 | GG10: 200 | GH10: 1440 | GI10: 192.619(A)(1) | GK10: 41101 | GL10: NO | GM10: PRESSURE DID NOT EXCEED MAOP | GN10: NO | GQ10: NO | GS10: MANUAL | GT10: MANUAL | GU10: 16005 | GV10: YES | HD10: NO | HK10: TYPE C GATHERING | HL10: NO | HQ10: NOTIFICATION FROM PUBLIC | HT10: NO, THE FACILITY WAS NOT MONITORED BY A CONTROLLER(S) AT THE TIME OF THE INCIDENT | IH10: NO | II10: NO | IN10: OTHER INCIDENT CAUSE | IO10: UNKNOWN | QS10: UNKNOWN | QU10: STILL UNDER INVESTIGATION, CAUSE OF INCIDENT TO BE DETERMINED* (*SUPPLEMENTAL REPORT REQUIRED) | WL10: JOSEPH STOVER | WM10: SR. SPECIALIST DOT COMPLIANCE | WN10: joseph.stover@energytransfer.com | WO10: 8323241027 | WT10: JUSTIN DAVIDSON | WU10: MANAGER DOT COMPLIANCE | WV10: 7138820590 | WW10: justin.davidson@energytransfer.com | WX10: ENERGY TRANSFER (ET) PERSONNEL RECEIVED A CALL FROM THE LANDOWNER AT 9:40 AM ON MARCH 7TH, 2025, OF A POTENTIAL LEAK IN AN ET ROW. ET PERSONNEL ARRIVED ON SITE AT 10:00AM AND STARTED TAKING PRECAUTIONARY MEASURES AND ISOLATING THE LINE. THE LINE WAS ISOLATED AT 11:44 AM. IT WAS NOT CONFIRMED THAT THE LEAK WAS ON THE GALVAN G13 LTS UNTIL 14:05 ON MARCH 11TH, 2025, AND IT WAS PREDICTED TO EXCEED THE COST REPORTING THRESHOLD. THE INCIDENT INVESTIGATION IS STILL UNDERWAY, AND THE LINE IS CURRENTLY OUT OF SERVICE. REMEDIATION IS PENDING RESULTS OF THE INVESTIGATION.
A11: 44 | B11: 45728 | C11: 2025 | D11: 20250025 | E11: 40864 | F11: SUPPLEMENTAL FINAL | G11: 40285 | H11: GULF RUN TRANSMISSION, LLC | I11: 1300 MAIN STREET | J11: HOUSTON | K11: TX | L11: 77002 | M11: 45703.84 | N11: CENTRAL | O11: NO | P11: 32.290899 | Q11: -92.626194 | R11: 1423646 | S11: 45703.887 | T11: 1423735 | U11: NATURAL GAS | W11: 22000 | X11: 0 | Y11: 0 | Z11: NO | AF11: 0 | AG11: NO | AM11: 0 | AN11: NORMAL OPERATION, INCLUDES PAUSES DURING MAINTENANCE | AO11: YES | AQ11: 45703.877 | AR11: 45704.167 | AT11: NO | AW11: NO | BI11: 0 | BJ11: 45703.84 | BK11: 45703.874 | BL11: 45703.877 | BM11: ONSHORE | BN11: LA | BO11: 71251 | BP11: Not Within a Municipality | BQ11: JACKSON | BR11: NOT APPLICABLE | BT11: VERNON COMPRESSOR STATION | BU11: CP_PANOLA COMPRESSOR LS TO VERNON COMPRESSOR RS | BV11: NO | BW11: OPERATOR-CONTROLLED PROPERTY | BX11: ABOVEGROUND | BY11: TYPICAL ABOVEGROUND FACILITY PIPING OR APPURTENANCE | CC11: NO | CZ11: INTERSTATE | DA11: ONSHORE COMPRESSOR STATION EQUIPMENT AND PIPING | DB11: ESD SYSTEM, BUT EXCLUDING PRODUCT DRAIN LINES AND TUBING | EO11: 2007 | EP11: 2007 | EQ11: CARBON STEEL | ES11: OTHER | FB11: LACK OF ESD VALVE CLOSURE | FC11: CLASS 1 LOCATION | FD11: NO | FF11: 990 | FH11: NO | FI11: NO | FL11: NO | FO11: 0 | FP11: 102960 | FQ11: 0 | FR11: 0 | FS11: 0 | FT11: 0 | FV11: 4.68 | FW11: 102960 | FX11: 0 | FY11: 0 | FZ11: 0 | GA11: 0 | GB11: NO | GF11: 989 | GG11: 1400000 | GH11: 1168 | GI11: 192.619(A)(2) | GK11: 39187 | GL11: NO | GM11: PRESSURE DID NOT EXCEED MAOP | GN11: NO | GQ11: NO | HK11: TRANSMISSION SYSTEM | HL11: YES | HM11: YES | HN11: YES | HO11: YES | HP11: NO | HQ11: SCADA-BASED INFORMATION (SUCH AS ALARM(S), ALERT(S), EVENT(S), AND/OR VOLUME OR PACK CALCULATIONS) | HT11: NO, THE OPERATOR DID NOT FIND THAT AN INVESTIGATION OF THE CONTROLLER(S) ACTIONS OR CONTROL ROOM ISSUES WAS NECESSARY DUE TO: (PROVIDE AN EXPLANATION FOR WHY THE OPERATOR DID NOT INVESTIGATE) | HU11: CONTROLLER ACTIONS DID NOT CONTRIBUTE TO THE EVENT | IH11: NO | II11: NO | IN11: EQUIPMENT FAILURE | IO11: MALFUNCTION OF CONTROL/RELIEF EQUIPMENT | OU11: MALFUNCTION OF CONTROL/RELIEF EQUIPMENT | PG11: YES | PH11: IMPROPER PRESSURE SWITCH SET POINT | PU11: YES | QE11: YES | QF11: THE PRESSURE SWITCH THAT ACTUATES THE ESD BLOW DOWN VALVE WAS SET INCORRECTLY. | VX11: YES | WL11: RYAN HESS | WM11: COMPLIANCE | WN11: ryan.hess@energytransfer.com | WO11: 903-720-5473 | WQ11: BOB MIDDLETON | WR11: bob.middleton@energytransfer.com | WS11: 318-5607428 | WT11: SUSIE SJULIN | WU11: COMPLIANCE DIRECTOR | WV11: 405-557-5271 | WW11: susie.sjulin@energytransfer.com | WX11: ON 2/15/2025 THE VERNON COMPRESSOR STATION LOST COMMERCIAL POWER. IN ADDITION, THE EMERGENCY GENERATOR FAILED TO START, AND THE STATION BATTERY UPS SYSTEM FAILED TO SWITCH TO BATTERY BACKUP. THE UPS IS USED TO MAINTAIN POWER TO STATION NETWORKS, PLC'S, AND HMIS FOR SHORT PERIODS OF TIME UNTIL EITHER COMMERCIAL OR EMERGENCY GENERATOR POWER BECOMES AVAILABLE. WITH NO POWER, A NORMAL STOP COMMAND WAS ISSUED TO ALL THREE STATION TURBINES. THE TURBINES STOPPED, THE UNIT BLOWDOWN VALVES OPENED, AND THE FUEL SUPPLY VALVES CLOSED. THE STATION ESD BLOWDOWN VALVES ARE DESIGNED TO DEFAULT TO THE FAIL-OPEN POSITION AND MUST BE MANUALLY RESET. STATION BLOWDOWN VALVES WERE SET TO OPEN AT 55PSI. THE ESD PRESSURE DROPPED BELOW 50PSI, WHICH ACTIVATED THE VALVES, AND BEGAN RELIEVING THE STATION PRESSURE. TECHNICIANS ARRIVED ON LOCATION AND BLOCKED IN THE STATION DURING THE BLOWDOWN PROCESS, PRIOR TO A FULL STATION BLOWDOWN. CORRECTIVE ACTIONS TAKEN TO HAVE THE STATION BACK ONLINE BY 2/16/2025 AT 4:00AM. REMEDIAL ACTIONS TAKEN, SMALL LEAK WAS FOUND ON THE ESD SYSTEM. THE ESD PILOTS ON BLOWDOWN VALVES WERE RESET TO 30PSI AND THE SIDE GATE ESD PILOTS WERE REST TO 45PSI. ORIGINAL CONSTRUCTION DESIGN WAS CHANGED FROM UTILIZING ESD GAS AS PILOT PRESSURE TO POWER GAS. ALL REGULATORS WERE TESTED AND TRENDED TO ENSURE PROPER OPERATION. GENERATOR LOGIC ISSUES WERE IDENTIFIED AND CORRECTED, THEN MULTIPLE SIMULATED POWER LOSS SCENARIOS WERE RUN TO ENSURE THE GENERATOR TRANSFERRED PROPERLY AND CARRIED THE STATION LOAD.
A12: 50 | B12: 45800 | C12: 2025 | D12: 20250056 | E12: 40937 | F12: ORIGINAL | G12: 18152 | H12: SEA ROBIN PIPELINE CO | I12: 1300 MAIN STREET | J12: HOUSTON | K12: TX | L12: 77002 | M12: 45681.452 | N12: CENTRAL | O12: YES | P12: 28.615134 | Q12: -90.251182 | R12: 1421791 | S12: 45681.499 | T12: 1421896, 1429408 | U12: NATURAL GAS | W12: 5718 | X12: 2318 | Y12: 0 | Z12: NO | AF12: 0 | AG12: NO | AM12: 0 | AN12: NORMAL OPERATION, INCLUDES PAUSES DURING MAINTENANCE | AO12: YES | AQ12: 45681.542 | AS12: YES | AT12: YES | AU12: OPERATOR | AV12: 45681.499 | AW12: NO | BC12: VALVE CLOSURE | BE12: 45681.562 | BF12: VALVE CLOSURE | BH12: 45681.542 | BI12: 0 | BJ12: 45772.094 | BK12: 45681.542 | BL12: 45772.094 | BM12: OFFSHORE | BT12: SEA ROBIN | BU12: 319B-2400 | CP12: 156 | CQ12: ON THE OUTER CONTINENTAL SHELF (OCS) | CV12: OCS-GULF OF AMERICA | CW12: SOUTH TIMBALIER | CX12: 151 | CY12: BELOW WATER, PIPE BURIED OR JETTED BELOW SEABED | CZ12: INTERSTATE | DA12: OFFSHORE PIPELINE, INCLUDING RISER AND RISER BEND | DB12: PIPE | DC12: PIPE BODY | DD12: 20 | DE12: NO | DF12: 0.469 | DG12: 52000 | DH12: API 5L X52 | DI12: DSAW | DK12: KAISER STEEL | DL12: COAL TAR | DN12: NO | EO12: 1976 | EP12: 1976 | EQ12: CARBON STEEL | ES12: LEAK | EV12: PINHOLE | FC12: CLASS 1 LOCATION | FD12: NO | FF12: 482 | FH12: NO | FI12: NO | FL12: NO | FO12: 0 | FP12: 20528 | FQ12: 8322 | FR12: 2457394 | FS12: 107500 | FT12: 0 | FV12: 3.59 | FW12: 2593744 | FX12: 0 | FY12: 0 | FZ12: 0 | GA12: 0 | GB12: NO | GF12: 850 | GG12: 0 | GH12: 1200 | GI12: 192.619(A)(2) | GK12: 28126 | GL12: NO | GM12: PRESSURE DID NOT EXCEED MAOP | GN12: NO | GQ12: NO | GS12: MANUAL | GT12: MANUAL | GU12: 66105 | GV12: NO | GY12: YES | HD12: NO | HK12: TRANSMISSION SYSTEM | HL12: YES | HM12: YES | HN12: YES | HO12: NO | HP12: NO | HQ12: OTHER | HR12: NOTIFIED BY ARENA PLATFORM | HT12: NO, THE OPERATOR DID NOT FIND THAT AN INVESTIGATION OF THE CONTROLLER(S) ACTIONS OR CONTROL ROOM ISSUES WAS NECESSARY DUE TO: (PROVIDE AN EXPLANATION FOR WHY THE OPERATOR DID NOT INVESTIGATE) | HU12: LEAK WAS TOO SMALL FOR SCADA TO DETECT. | IH12: NO | II12: NO | IN12: OTHER INCIDENT CAUSE | IO12: UNKNOWN | QS12: UNKNOWN | QU12: STILL UNDER INVESTIGATION, CAUSE OF INCIDENT TO BE DETERMINED* (*SUPPLEMENTAL REPORT REQUIRED) | WL12: PEGGY WEST | WM12: MANAGER DOT COMPLIANCE | WN12: peggy.west@energytransfer.com | WO12: 4092023088 | WT12: PEGGY WEST | WU12: MANAGER DOT COMPLIANCE | WV12: 4092023088 | WW12: peggy.west@energytransfer.com | WX12: AT APPROXIMATELY 1051 ON 01/24/25, OPERATIONS RECEIVED A CALL FROM A 3RD PARTY REPORTING BUBBLES IN THE AREA NEAR THE SEA ROBIN 319B-2400 IN SOUTH TIMBALIER 151 (ST 151). NRC WAS CALLED REPORTING THE BUBBLES IN ST151 (NRC#1421791, 48HR UPDATE#1421896). AN OVERFLIGHT WAS CONDUCTED TO VERIFY THE LOCATION OF THE BUBBLES. PIPELINE WAS ISOLATED ON 01/24/25 AT 1330. OVERFLIGHTS WERE CONDUCTED DAILY TO MONITOR THE AREA FOR ANY CHANGES AS WEATHER PERMITTED. DUE TO WEATHER CONDITIONS, SEA STATES AND DSV AVAILABILITY, THE REPAIR CONTRACTOR WAS NOT ABLE TO DEPLOY UNTIL 4/24/25. DIVERS VERIFIED LEAK LOCATION ON 04/25/25 AT 0215 ON THE SEA ROBIN 319B-2400 PIPELINE. AN ATTEMPT WAS MADE TO REPAIR THE LEAK LOCATION. THE REPAIR WAS NOT COMPLETED DUE TO THE CLAMP NOT SEALING. A SPECIALIZED CLAMP IS ON ORDER. THE PIPELINE REMAINS ISOLATED UNTIL THE CLAMP CAN BE INSTALLED. THE 48HR NRC NOTIFICATION WAS UPDATED ON 04/25/25 AT 0859 TO REFLECT THE CHANGE FROM UNKNOWN OWNER TO SEA ROBIN PIPELINE. (#1429408)
A13: 51 | B13: 45702 | C13: 2025 | D13: 20250014 | E13: 40504 | F13: ORIGINAL FINAL | G13: 40285 | H13: GULF RUN TRANSMISSION, LLC | I13: 1300 MAIN STREET | J13: HOUSTON | K13: TX | L13: 77002 | M13: 45681.319 | N13: CENTRAL | O13: YES | P13: 32.290899 | Q13: -92.626194 | R13: 1421766 | S13: 45681.361 | T13: 1422317 | U13: NATURAL GAS | W13: 22000 | X13: 0 | Y13: 0 | Z13: NO | AF13: 0 | AG13: NO | AM13: 0 | AN13: NORMAL OPERATION, INCLUDES PAUSES DURING MAINTENANCE | AO13: YES | AQ13: 45681.309 | AR13: 45681.875 | AT13: YES | AU13: OPERATOR | AV13: 45681.3 | AW13: NO | BI13: 0 | BJ13: 45681.309 | BK13: 45681.306 | BL13: 45681.309 | BM13: ONSHORE | BN13: LA | BO13: 71251 | BP13: Not Within a Municipality | BQ13: JACKSON | BR13: NOT APPLICABLE | BT13: VERNON COMPRESSOR STATION | BU13: CP_PANOLA COMPRESSOR LS TO VERNON COMPRESSOR RS | BV13: NO | BW13: OPERATOR-CONTROLLED PROPERTY | BX13: ABOVEGROUND | BY13: TYPICAL ABOVEGROUND FACILITY PIPING OR APPURTENANCE | CC13: NO | CZ13: INTERSTATE | DA13: ONSHORE COMPRESSOR STATION EQUIPMENT AND PIPING | DB13: ESD SYSTEM, BUT EXCLUDING PRODUCT DRAIN LINES AND TUBING | EO13: 2007 | EP13: 2007 | EQ13: CARBON STEEL | ES13: OTHER | FB13: ESD VALVE FAILURE | FC13: CLASS 1 LOCATION | FD13: NO | FF13: 990 | FH13: NO | FI13: NO | FL13: NO | FO13: 0 | FP13: 84040 | FQ13: 0 | FR13: 15000 | FS13: 0 | FT13: 0 | FV13: 3.82 | FW13: 99040 | FX13: 0 | FY13: 0 | FZ13: 0 | GA13: 0 | GB13: NO | GF13: 900 | GG13: 1300000 | GH13: 1168 | GI13: 192.619(A)(2) | GK13: 39187 | GL13: NO | GM13: PRESSURE DID NOT EXCEED MAOP | GN13: NO | GQ13: NO | HK13: TRANSMISSION SYSTEM | HL13: YES | HM13: YES | HN13: YES | HO13: YES | HP13: YES | HQ13: LOCAL OPERATING PERSONNEL, INCLUDING CONTRACTORS | HS13: OPERATOR EMPLOYEE | HT13: NO, THE OPERATOR DID NOT FIND THAT AN INVESTIGATION OF THE CONTROLLER(S) ACTIONS OR CONTROL ROOM ISSUES WAS NECESSARY DUE TO: (PROVIDE AN EXPLANATION FOR WHY THE OPERATOR DID NOT INVESTIGATE) | HU13: CONTROLLER ACTIONS DID NOT CONTRIBUTE TO THE EVENT | IH13: NO | II13: NO | IN13: EQUIPMENT FAILURE | IO13: MALFUNCTION OF CONTROL/RELIEF EQUIPMENT | OU13: MALFUNCTION OF CONTROL/RELIEF EQUIPMENT | PF13: YES | QE13: YES | QF13: ESD VALVE FAILURE | VX13: YES | WL13: RYAN HESS | WM13: COMPLIANCE | WN13: ryan.hess@energytransfer.com | WO13: 903-720-5473 | WQ13: BOB MIDDLETON | WR13: bob.middleton@energytransfer.com | WS13: 318-5607428 | WT13: JIMMY CROSS | WU13: COMPLIANCE MANAGER | WV13: 405-576-8230 | WW13: jimmy.cross@energytransfer.com | WX13: A CONNECTION FAULT PRODUCED A FLAME DETECTOR INPUT FAILURE IN UNIT 3 BUILDING, WHICH CAUSED UNIT 3 TO SHUT DOWN AND ESD. UNIT 3 FUEL SUPPLY VALVE DID NOT CLOSE WHEN UNIT 3 BLOWDOWN VALVE OPENED. CAUSING A DRAIN ON STATION SYSTEM PRESSURE. THIS STATION HAS A PNEUMATIC/ELECTRICAL ESD. THE LOW ESD PRESSURE IS 55PSI. WHEN ESD FELL AT OR BELOW 55PSI THE STATION ESD.
