Workbook

Sheet Summary
A1: Summary of Selected Results from Energy Transfer-related hazardous liquids spills (2018-present)
A3: Number of Incidents | B3: =COUNT('PHMSA records'!A:A) -> 300 | E3: Impacts
A4: Start of Time Period | B4: 43101 | E4: Injuries | F4: =COUNTIF('PHMSA records'!AG:AG, "YES") -> 2
A5: End of Time Period | B5: 45838 | E5: Deaths | F5: =COUNTIF('PHMSA records'!Z:Z, "YES") -> 1
A6: Average Number of Days Between Incidents | B6: =(B5-B4)/B3 -> 9.1233333 | E6: Ignition | F6: =COUNTIF('PHMSA records'!BH:BH, "YES") -> 10
E7: Explosion | F7: =COUNTIF('PHMSA records'!BM:BM, "YES") -> 2
A8: Total Volume (Unintentional Release) | E8: Wildlife | F8: =COUNTIF('PHMSA records'!FY:FY, "YES") -> 6
A9: in barrels | B9: =SUM('PHMSA records'!W:W) -> 91290.14 | E9: Soil Contamination | F9: =COUNTIF('PHMSA records'!GC:GC, "YES") -> 246
A10: in gallons | B10: =B9*42 -> 3834185.9 | E10: Water Contamination | F10: =COUNTIF('PHMSA records'!GK:GK, "YES") -> 25
A11: in Olympic-sized swimming pools | B11: =B10/660000 -> 5.8093725 | E11: Groundwater Contamination | F11: =COUNTIF('PHMSA records'!GN:GN, "YES") -> 7
E12: Drinking Water Contamination | F12: =COUNTIF('PHMSA records'!GO:GO, "YES") -> 1
A13: Totals by Product | B13: # incidents | C13: Total Volume | E13: High-Consequence Area | F13: =COUNTIF('PHMSA records'!GU:GU, "YES") -> 129
A14: Crude Oil | B14: =COUNTIF('PHMSA records'!R:R, "CRUDE OIL") -> 249 | C14: =SUMIF('PHMSA records'!R:R, "CRUDE OIL", 'PHMSA records'!W:W) -> 31859.72 | E14: High-Population Area | F14: =COUNTIF('PHMSA records'!GX:GX, "YES") -> 96
A15: Refined Petroleum Products | B15: =COUNTIF('PHMSA records'!R:R, "REFINED AND/OR PETROLEUM PRODUCT (NON-HVL) WHICH IS A LIQUID AT AMBIENT CONDITIONS") -> 30 | C15: =SUMIF('PHMSA records'!R:R, "REFINED AND/OR PETROLEUM PRODUCT (NON-HVL) WHICH IS A LIQUID AT AMBIENT CONDITIONS", 'PHMSA records'!W:W) -> 6837.59 | E15: Total Property Damage | F15: =SUM('PHMSA records'!HM:HM) -> 96458844
A16: HVLs | B16: =COUNTIF('PHMSA records'!R:R, "HVL OR OTHER FLAMMABLE OR TOXIC FLUID WHICH IS A GAS AT AMBIENT CONDITIONS") -> 21 | C16: =SUMIF('PHMSA records'!R:R, "HVL OR OTHER FLAMMABLE OR TOXIC FLUID WHICH IS A GAS AT AMBIENT CONDITIONS", 'PHMSA records'!W:W) -> 52592.83
E17: Causes
A18: Report Status | E18: Equipment Failure | F18: =COUNTIF('PHMSA records'!JX:JX, "EQUIPMENT FAILURE") -> 109
A19: Original | B19: =COUNTIF('PHMSA records'!F:F, "ORIGINAL") -> 19 | E19: Corrosion | F19: =COUNTIF('PHMSA records'!JX:JX, "CORROSION FAILURE") -> 101
A20: Original Final | B20: =COUNTIF('PHMSA records'!F:F, "ORIGINAL FINAL") -> 145 | E20: Incorrect Operation | F20: =COUNTIF('PHMSA records'!JX:JX, "INCORRECT OPERATION") -> 34
A21: Supplemental | B21: =COUNTIF('PHMSA records'!F:F, "SUPPLEMENTAL") -> 5 | E21: Other Accident Cause | F21: =COUNTIF('PHMSA records'!JX:JX, "OTHER ACCIDENT CAUSE") -> 17
A22: Supplemental Final | B22: =COUNTIF('PHMSA records'!F:F, "SUPPLEMENTAL FINAL") -> 131 | E22: Material Failure of Pipe or Weld | F22: =COUNTIF('PHMSA records'!JX:JX, "MATERIAL FAILURE OF PIPE OR WELD") -> 15
E23: Excavation Damage | F23: =COUNTIF('PHMSA records'!JX:JX, "EXCAVATION DAMAGE") -> 9
E24: Natural Force Damage | F24: =COUNTIF('PHMSA records'!JX:JX, "NATURAL FORCE DAMAGE") -> 8
E25: Other Outside Force Damage | F25: =COUNTIF('PHMSA records'!JX:JX, "OTHER OUTSIDE FORCE DAMAGE") -> 7

Sheet PHMSA records
B1: REPORT_RECEIVED_DATE | C1: IYEAR | D1: REPORT_NUMBER | E1: SUPPLEMENTAL_NUMBER | F1: REPORT_TYPE | G1: OPERATOR_ID | H1: NAME | I1: OPERATOR_STREET_ADDRESS | J1: OPERATOR_CITY_NAME | K1: OPERATOR_STATE_ABBREVIATION | L1: OPERATOR_POSTAL_CODE | M1: LOCAL_DATETIME | N1: TIME_ZONE | O1: DAYLIGHT_SAVINGS_IND | P1: LOCATION_LATITUDE | Q1: LOCATION_LONGITUDE | R1: COMMODITY_RELEASED_TYPE | S1: COMMODITY_SUBTYPE | T1: COMMODITY_DETAILS | U1: BLEND_DETAILS | V1: BIO_DIESEL_DETAILS | W1: UNINTENTIONAL_RELEASE_BBLS | X1: INTENTIONAL_RELEASE_BBLS | Y1: RECOVERED_BBLS | Z1: FATALITY_IND | AA1: NUM_EMP_FATALITIES | AB1: NUM_CONTR_FATALITIES | AC1: NUM_ER_FATALITIES | AD1: NUM_WORKER_FATALITIES | AE1: NUM_GP_FATALITIES | AF1: FATAL | AG1: INJURY_IND | AH1: NUM_EMP_INJURIES | AI1: NUM_CONTR_INJURIES | AJ1: NUM_ER_INJURIES | AK1: NUM_WORKER_INJURIES | AL1: NUM_GP_INJURIES | AM1: INJURE | AN1: ACCIDENT_IDENTIFIER | AO1: ACCIDENT_DETAILS | AP1: OPERATOR_TYPE | AQ1: INCIDENT_IDENTIFIED_DATETIME | AR1: SYSTEM_PART_INVOLVED | AS1: ON_OFF_SHORE | AT1: STATUS_WHEN_IDENTIFIED | AU1: SHUTDOWN_DUE_ACCIDENT_IND | AV1: SHUTDOWN_EXPLAIN | AW1: SHUTDOWN_DATETIME | AX1: RESTART_DATETIME | AY1: STILL_SHUTDOWN_IND | AZ1: COMMUNICATION_STATE_FED_IND | BA1: PARTY_INITIATED_COMMUNICATION | BB1: INITIAL_RESPONDER_COM_DATETIME | BC1: ON_SITE_DATETIME | BD1: CONFIRMED_DISCOVERY_DATETIME | BE1: NRC_RPT_DATETIME | BF1: NRC_RPT_NUM | BG1: ADDITIONAL_NRC_REPORT_NUMBERS | BH1: IGNITE_IND | BI1: IGNITE_DATETIME | BJ1: HOW_EXTINGUISHED | BK1: HOW_EXTINGUISHED_OTHER_DETAIL | BL1: CONSUMED_BY_FIRE_IN_BARRELS | BM1: EXPLODE_IND | BN1: UPSTREAM_ACTION_TAKEN | BO1: UPSTREAM_OPRTNL_CNTRL_DETAIL | BP1: UPSTREAM_VALVE_CLOSE_DATETIME | BQ1: UPSTREAM_VALVE_TYPE_IND | BR1: DOWNSTREAM_ACTION_TAKEN | BS1: DOWNSTREAM_OPRTNL_CNTRL_DETAIL | BT1: DOWNSTREAM_VLV_CLOSE_DATETIME | BU1: DOWNSTREAM_VALVE_TYPE_IND | BV1: NOTIFY_QUALIFIED_INDIV_IND | BW1: QUALIFIED_INDIV_NOTIF_DATETIME | BX1: OIL_SPILL_REMOVAL_ORG_IND | BY1: OSRO_ACTIVATED_DATETIME | BZ1: OSRO_ARRIVED_ON_SITE_DT | CA1: NUM_PUB_EVACUATED | CB1: PIPE_FAC_NAME | CC1: SEGMENT_NAME | CD1: ONSHORE_STATE_ABBREVIATION | CE1: ONSHORE_POSTAL_CODE | CF1: ONSHORE_CITY_NAME | CG1: ONSHORE_COUNTY_NAME | CH1: DESIGNATED_LOCATION | CI1: DESIGNATED_NAME | CJ1: FEDERAL | CK1: LOCATION_TYPE | CL1: INCIDENT_AREA_TYPE | CM1: INCIDENT_AREA_SUBTYPE | CN1: INCIDENT_AREA_DETAILS | CO1: DEPTH_OF_COVER | CP1: CROSSING | CQ1: BRIDGE_CROSSING_IND | CR1: BRIDGE_TYPE | CS1: RAILROAD_CROSSING_IND | CT1: RAILROAD_TYPE | CU1: ROAD_CROSSING_IND | CV1: ROAD_TYPE | CW1: WATER_CROSSING_IND | CX1: WATER_TYPE | CY1: WATER_NAME | CZ1: WATER_DEPTH | DA1: WATER_SUBTYPE | DB1: CROSSING_100_FEET | DC1: OFF_WATER_DEPTH | DD1: OFF_ACCIDENT_ORIGIN | DE1: OFFSHORE_STATE_ABBREVIATION | DF1: OFF_INSTATE_AREA | DG1: OFF_INSTATE_BLOCK | DH1: OFFSHORE_COUNTY_NAME | DI1: OCS_TYPE | DJ1: OFF_OCS_AREA | DK1: OFF_OCS_BLOCK | DL1: OFF_AREA_ACCIDENT_TYPE | DM1: PIPE_FACILITY_TYPE | DN1: ITEM_INVOLVED | DO1: PIPE_TYPE | DP1: PUDDLE_WELD_IND | DQ1: PIPE_DIAMETER | DR1: PIPE_WALL_THICKNESS | DS1: PIPE_SMYS | DT1: PIPE_SPECIFICATION | DU1: PIPE_SEAM_TYPE | DV1: PIPE_SEAM_DETAILS | DW1: PIPE_MANUFACTURER | DX1: PIPE_COATING_TYPE | DY1: PIPE_COATING_DETAILS | DZ1: COATING_APPLIED_IND | EA1: WELD_SUBTYPE | EB1: WELD_DETAILS | EC1: DIFFERENT_GIRTH_WELD_IND | ED1: DIFF_GIRTH_WELD_WALL_THICKNESS | EE1: DIFF_GIRTH_WELD_SMYS | EF1: DIFF_GIRTH_WELD_SPECIFICATION | EG1: DIFF_GIRTH_WELD_SEAM_TYPE | EH1: DIFF_GIRTH_WELD_SEAM_DETAIL | EI1: DIFF_GIRTH_WELD_MANUFACTURER | EJ1: DIFF_GIRTH_WELD_COATING_TYPE | EK1: DIFF_GIRTH_WELD_COATING_DETAIL | EL1: DIFF_GIRTH_WELD_CTNG_APPLD_IND | EM1: VALVE_TYPE | EN1: VALVE_MAINLINE_TYPE | EO1: VALVE_MAINLINE_DETAILS | EP1: VALVE_MANUFACTURER | EQ1: PUMP_TYPE | ER1: PUMP_TYPE_DETAILS | ES1: PUMP_SERVICE_TYPE | ET1: PUMP_SERVICE_TYPE_DETAILS | EU1: TUBING_MATERIAL | EV1: TUBING_TYPE | EW1: TANK_VESSEL_SUBTYPE | EX1: TANK_VESSEL_DETAILS | EY1: TANK_TYPE | EZ1: TANK_MAX_PRESSURE | FA1: TANK_SET_POINT_RELIEF_DEVICE | FB1: TANK_RELIEF_VALVE_ACTVTD_IND | FC1: TANK_MOP_EXCEEDED_IND | FD1: SAFE_FILL_LEVEL | FE1: SAFE_FILL_LEVEL_EXCEEDED_IND | FF1: API_STD_OUT_OF_SERVICE_YEAR | FG1: API_STD_OUT_OF_SRVC_NONE_IND | FH1: API_STD_IN_SERVICE_YEAR | FI1: API_STD_NO_IN_SERVICE_IND | FJ1: ITEM_INVOLVED_DETAILS | FK1: INSTALLATION_YEAR | FL1: MANUFACTURED_YEAR | FM1: MATERIAL_INVOLVED | FN1: MATERIAL_DETAILS | FO1: RELEASE_TYPE | FP1: PUNCTURE_AXIAL | FQ1: PUNCTURE_CIRCUM | FR1: LEAK_TYPE | FS1: LEAK_TYPE_OTHER | FT1: RUPTURE_ORIENT | FU1: RUPTURE_DETAILS | FV1: RUPTURE_WIDTH | FW1: RUPTURE_LENGTH | FX1: RELEASE_TYPE_DETAILS | FY1: WILDLIFE_IMPACT_IND | FZ1: FISH_AQUATIC_IMPACT_IND | GA1: BIRDS_IMPACT_IND | GB1: TERRESTRIAL_IMPACT_IND | GC1: SOIL_CONTAMINATION | GD1: LONG_TERM_ASSESSMENT | GE1: REMEDIATION_IND | GF1: SURFACE_WATER_REMED_IND | GG1: GROUNDWATER_REMED_IND | GH1: SOIL_REMED_IND | GI1: VEGETATION_REMED_IND | GJ1: WILDLIFE_REMED_IND | GK1: WATER_CONTAM_IND | GL1: OCEAN_SEAWATER_IND | GM1: SURFACE_CONTAM_IND | GN1: GROUNDWATER_CONTAM_IND | GO1: DRINKING_WATER_CONTAM_IND | GP1: PRIVATE_WELL_CONTAM_IND | GQ1: PUBLIC_WATER_CONTAM_IND | GR1: AMOUNT_RELEASED | GS1: REL_WATER_NAME | GT1: COULD_BE_HCA | GU1: COMMODITY_REACHED_HCA | GV1: COMMERCIALLY_NAV_IND | GW1: COMMERCIALLY_NAV_YES_NO | GX1: HIGH_POP_IND | GY1: HIGH_POP_YES_NO | GZ1: OTHER_POP_IND | HA1: OTHER_POP_YES_NO | HB1: USA_DRINKING_IND | HC1: USA_DRINKING_YES_NO | HD1: USA_ECOLOGICAL_IND | HE1: USA_ECOLOGICAL_YES_NO | HF1: EST_COST_OPER_PAID | HG1: EST_COST_GAS_RELEASED | HH1: EST_COST_PROP_DAMAGE | HI1: EST_COST_EMERGENCY | HJ1: EST_COST_ENVIRONMENTAL | HK1: EST_COST_OTHER | HL1: EST_COST_OTHER_DETAILS | HM1: PRPTY | HN1: NUM_PERSONS_HOSP_NOT_OVNGHT | HO1: NUM_INJURED_TREATED_BY_EMT | HP1: NUM_RESIDENT_BUILDING_AFFCTD | HQ1: NUM_BUSINESS_BUILDING_AFFCTD | HR1: ACCIDENT_PSIG | HS1: MOP_PSIG | HT1: MOP_CFR_SECTION | HU1: MOP_CFR_SECTION_DETAILS | HV1: MAOP_ESTABLISHED_DATE | HW1: MAOP_REVERSAL_FLOW_IND | HX1: SURGE_ANALYSIS_DATE | HY1: ACCIDENT_PRESSURE | HZ1: PRESSURE_RESTRICTION_IND | IA1: EXCEED_RESTRICTION_IND | IB1: PHMSA_RESTRICTION_IND | IC1: LENGTH_SEGMENT_ISOLATED | ID1: INTERNAL_INSPECTION_IND | IE1: DIAMETER_CHANGE_IND | IF1: UNSUITABLE_MAINLINE_IND | IG1: TIGHT_MITERED_IND | IH1: OTHER_RESTRICTIONS_IND | II1: EXTRA_THICK_WALL_IND | IJ1: OTHER_INSPECTION_IND | IK1: INTERNAL_INSPECTION_DETAILS | IL1: OPERATION_COMPLICATIONS_IND | IM1: EXCESSIVE_DEBRIS_IND | IN1: LOW_OP_PRESSURE_IND | IO1: LOW_FLOW_IND | IP1: INCOMPAT_COMMOD_IND | IQ1: OTHER_COMPLICATIONS_IND | IR1: INSPECT_COMP_DETAILS | IS1: PIPELINE_FUNCTION | IT1: SCADA_IN_PLACE_IND | IU1: SCADA_OPERATING_IND | IV1: SCADA_FUNCTIONAL_IND | IW1: SCADA_DETECTION_IND | IX1: SCADA_CONF_IND | IY1: CPM_IN_PLACE_IND | IZ1: CPM_OPERATING_IND | JA1: CPM_FUNCTIONAL_IND | JB1: CPM_DETECTION_IND | JC1: CPM_CONF_IND | JD1: INVESTIGATION_STATUS | JE1: INVESTIGATION_STATUS_DETAILS | JF1: INVEST_SCHEDULE_IND | JG1: INVEST_NO_SCHEDULE_IND | JH1: INVEST_NO_SCHEDULE_IND_DETAILS | JI1: INVEST_NO_CONTROL_ROOM_IND | JJ1: INVEST_NO_CONTROLLER_IND | JK1: INVEST_INCORRECT_ACTION_IND | JL1: INVEST_FATIGUE_IND | JM1: INVEST_INCORRECT_PROCEDURE_IND | JN1: INVEST_INCORRECT_CONTROL_IND | JO1: INVEST_MAINT_IND | JP1: INVEST_OTHER_IND | JQ1: INVEST_OTHER_IND_DETAILS | JR1: EMPLOYEE_DRUG_TEST_IND | JS1: CONTRACTOR_DRUG_TEST_IND | JT1: NUM_EMPLOYEES_TESTED | JU1: NUM_EMPLOYEES_FAILED | JV1: NUM_CONTRACTORS_TESTED | JW1: NUM_CONTRACTORS_FAILED | JX1: CAUSE | JY1: CAUSE_DETAILS | JZ1: INTERNAL_EXTERNAL | KA1: VISUAL_EXAM_RESULTS | KB1: VISUAL_EXAM_DETAILS | KC1: GALVANIC_CORROSION_IND | KD1: ATMOSPHERE_CORROSION_IND | KE1: STRAY_CURRENT_CORROSION_IND | KF1: MICROBIOLOGICAL_CORROSION_IND | KG1: SELECTIVE_SEAM_CORROSION_IND | KH1: OTHER_CORROSION_IND | KI1: CORROSION_TYPE_DETAILS | KJ1: STRAY_CURRENT_TYPE | KK1: STRAY_CURRENT_DETAILS | KL1: FIELD_EXAM_BASIS_IND | KM1: METALLURGICAL_BASIS_IND | KN1: OTHER_BASIS_IND | KO1: CORROSION_BASIS_DETAILS | KP1: UNDERGROUND_LOCATION | KQ1: UNDER_CATHODIC_PROTECTION_IND | KR1: CATHODIC_PRO_START_YEAR | KS1: SHIELDING_EVIDENT | KT1: CATHODIC_SURVEY_TYPE | KU1: CP_ANNUAL_SURVEY_IND | KV1: CLOSE_INTERVAL_SURVEY_IND | KW1: OTHER_CP_SURVEY_IND | KX1: CP_ANNUAL_SURVEY_YEAR | KY1: CLOSE_INTERVAL_SURVEY_YEAR | KZ1: OTHER_CP_SURVEY_YEAR | LA1: OTHER_CP_SURVEY_DETAILS | LB1: EXTERNALLY_COATED | LC1: PRIOR_DAMAGE | LD1: INT_VISUAL_EXAM_RESULTS | LE1: INT_VISUAL_EXAM_DETAILS | LF1: INT_CORROSIVE_COMMODITY_IND | LG1: INT_WATER_ACID_IND | LH1: INT_MICROBIOLOGICAL_IND | LI1: INT_EROSION_IND | LJ1: INT_OTHER_CORROSION_IND | LK1: INT_CORROSION_TYPE_DETAILS | LL1: INT_FIELD_EXAM_BASIS_IND | LM1: INT_METALLURGICAL_BASIS_IND | LN1: INT_OTHER_BASIS_IND | LO1: INT_CORROSION_BASIS_DETAILS | LP1: INT_LOW_POINT_PIPE_LOC_IND | LQ1: INT_ELBOW_LOC_IND | LR1: INT_DEAD_LEG_LOC_IND | LS1: INT_OTHER_LOC_IND | LT1: CORROSION_LOCATION_DETAILS | LU1: CORROSION_INHIBITORS | LV1: CORROSION_LINING | LW1: CLEANING_DEWATERING | LX1: CORROSION_COUPONS | LY1: NATURAL_FORCE_TYPE | LZ1: EARTH_SUBTYPE | MA1: HEAVY_RAINS_SUBTYPE | MB1: LIGHTNING_SUBTYPE | MC1: TEMPERATURE_SUBTYPE | MD1: NF_OTHER_DETAILS | ME1: NF_EXTREME_WEATHER_IND | MF1: NF_HURRICANE_IND | MG1: NF_TROPICAL_STORM_IND | MH1: NF_TORNADO_IND | MI1: NF_OTHER_IND | MJ1: NF_EXTREME_WEATHER_DETAILS | MK1: EX_PARTY_TYPE | ML1: PRIOR_NOTIFICATION_IND | MM1: ONE_CALL_SYSTEM_IND | MN1: EXCAVATOR_IND | MO1: CONTRACTOR_IND | MP1: LANDOWNER_IND | MQ1: STATE_LAW_EXEMPT_IND | MR1: STATE_LAW_EXEMPT_TYPE | MS1: STATE_LAW_EXEMPT_DETAIL | MT1: STATE_LAW_EXEMPT_AUTHORITY | MU1: STATE_LAW_EXEMPT_CRITERIA | MV1: NOTIFY_CGA_DIRT | MW1: PUBLIC_ROW_IND | MX1: PUBLIC_SUBTYPE | MY1: PRIVATE_ROW_IND | MZ1: PRIVATE_SUBTYPE | NA1: PIPELINE_EASEMENT_ROW_IND | NB1: POWER_TRANSMISSION_ROW_IND | NC1: RAILROAD_ROW_IND | ND1: PUBLIC_UTIL_EASEMENT_ROW_IND | NE1: FEDERAL_LAND_ROW_IND | NF1: UNKNOWN_ROW_IND | NG1: JOINT_TRENCH_IND | NH1: CROSS_BORE_IND | NI1: DEPTH_OF_GRADE | NJ1: DEPTH_OF_GRADE_DETAIL | NK1: EXCAVATOR_TYPE | NL1: EXCAVATOR_EQUIPMENT | NM1: WORK_PERFORMED | NN1: ONE_CALL_NOTIFIED_IND | NO1: ONE_CALL_TICKET_NUM | NP1: ONE_CALL_CENTER_NAME | NQ1: WHITE_LINED_IND | NR1: LOCATOR_TYPE | NS1: VISIBLE_MARKS | NT1: SERVICE_INTERRUPTION | NU1: SERVICE_INTERRUPTION_HOURS | NV1: ROOT_CAUSE_CATEGORY | NW1: ROOT_CAUSE_TYPE | NX1: ROOT_CAUSE_TYPE_OTHER | NY1: OUTSIDE_FORCE_TYPE | NZ1: VEHICLE_SUBTYPE | OA1: OSF_HURRICANE_IND | OB1: OSF_TROPICAL_STORM_IND | OC1: OSF_TORNADO_IND | OD1: OSF_HEAVY_RAINS_IND | OE1: OSF_OTHER_WEATHER_IND | OF1: OSF_OTHER_WEATHER_DETAILS | OG1: INTENTIONAL_SUBTYPE | OH1: INTENTIONAL_DETAILS | OI1: OSF_OTHER_DETAILS | OJ1: DRIVER_ISSUED_CITATION_IND | OK1: CITATION_SPEED_IND | OL1: CITATION_RECKLESS_IND | OM1: CITATION_DUI_IND | ON1: CITATION_OTHER_IND | OO1: CITATION_OTHER_DETAIL | OP1: DRIVER_IN_CONTROL_IND | OQ1: ESTIMATED_SPEED | OR1: ESTIMATED_SPEED_UNKNOWN_IND | OS1: VEHICLE_TYPE | OT1: VEHICLE_TRAVEL_FROM | OU1: VEHICLE_TRAVEL_DISTANCE_FT | OV1: PROTECTIONS_INSTALLED_IND | OW1: PROTECTION_BOLLARDS_POST_IND | OX1: PROTECTION_BARRICADES_IND | OY1: PROTECTION_GUARD_RAILS_IND | OZ1: PROTECTION_OTHER_IND | PA1: PROTECTION_OTHER_DETAIL | PB1: FIELD_EXAM_IND | PC1: METALLURGICAL_IND | PD1: OTHER_ANALYSIS_IND | PE1: OTHER_ANALYSIS_DETAILS | PF1: STILL_UNDER_INVEST_IND | PG1: FAILURE_TYPE | PH1: FATIGUE_VIBR_RELATED | PI1: FAILURE_SUBTYPE | PJ1: FATIGUE_VIBR_RELATED_OTHER | PK1: MECHANICAL_STRESS | PL1: OTHER_FACTOR | PM1: OTHER_FACTOR_DETAILS | PN1: STRESS_SUBTYPE | PO1: STRESS_DETAILS | PP1: ADDITIONAL_DENT_IND | PQ1: ADDITIONAL_GOUGE_IND | PR1: ADDITIONAL_PIPE_BEND_IND | PS1: ADDITIONAL_ARC_BURN_IND | PT1: ADDITIONAL_CRACK_IND | PU1: ADDITIONAL_LACK_FUSION_IND | PV1: ADDITIONAL_LAMINATION_IND | PW1: ADDITIONAL_BUCKLE_IND | PX1: ADDITIONAL_WRINKLE_IND | PY1: PWF_ADDL_MISALIGNMENT_IND | PZ1: ADDITIONAL_BURNT_STEEL_IND | QA1: PWF_ADDITIONAL_OTHER_IND | QB1: EQ_FAILURE_TYPE | QC1: CONTROL_VALVE_IND | QD1: INSTRUMENTATION_IND | QE1: SCADA_IND | QF1: COMMUNICATIONS_IND | QG1: BLOCK_VALVE_IND | QH1: CHECK_VALVE_IND | QI1: RELIEF_VALVE_IND | QJ1: POWER_FAILURE_IND | QK1: STOPPLE_CONTROL_FITTING_IND | QL1: ESD_SYSTEM_FAILURE_IND | QM1: OTHER_CONTROL_RELIEF_IND | QN1: OTHER_CONTROL_RELIEF_DETAILS | QO1: OTHER_PUMP_IND | QP1: OTHER_PUMP_DETAILS | QQ1: OTHER_STRIPPED_IND | QR1: OTHER_STRIPPED_DETAILS | QS1: OTHER_NON_THREADED_IND | QT1: OTHER_NON_THREADED_DETAILS | QU1: FAILURE_DETAILS | QV1: ADDITIONAL_VIBRATION_IND | QW1: ADDITIONAL_OVERPRESSURE_IND | QX1: ADDITIONAL_SUPPORT_IND | QY1: ADDITIONAL_DEFECT_IND | QZ1: ADDITIONAL_ELECTRICITY_IND | RA1: ADDITIONAL_INSTALLATION_IND | RB1: ADDITIONAL_IMPROPER_MNTNCE_IND | RC1: ADDITIONAL_MISMATCH_IND | RD1: ADDITIONAL_DISSIMILAR_IND | RE1: ADDITIONAL_BREAKDOWN_IND | RF1: ADDITIONAL_VALVE_IND | RG1: ADDITIONAL_ALARM_IND | RH1: IEF_ADDL_MISALIGNMENT_IND | RI1: ADDITIONAL_THERMAL_IND | RJ1: ADDITIONAL_EROSION_WEAR_IND | RK1: EQ_ADDITIONAL_OTHER_IND | RL1: EQ_ADDITIONAL_OTHER_DETAILS | RM1: OPERATION_TYPE | RN1: OVERFLOW_OTHER_IND | RO1: OVERFLOW_OTHER_DETAILS | RP1: OPERATION_DETAILS | RQ1: RELATED_INADEQUATE_PROC_IND | RR1: RELATED_NO_PROC_IND | RS1: RELATED_FAILURE_FOLLOW_IND | RT1: RELATED_OTHER_IND | RU1: OPERATION_RELATED_DETAILS | RV1: CATEGORY_TYPE | RW1: OPERATOR_QUALIFICATION_IND | RX1: QUALIFIED_INDIVIDUALS | RY1: OTHER_TYPE | RZ1: MISC_DETAILS | SA1: UNKNOWN_SUBTYPE | SB1: INCIDENT_UNKNOWN_COMMENTS | SC1: COLLECTED_DATA_IND | SD1: AXIAL_MAGNETIC_FLX_LKG_IND | SE1: CIR_TRN_WAVE_MGN_FLX_LKG_IND | SF1: ULTRASONIC_IND | SG1: GEOMETRY_DEFORMATION_IND | SH1: EMAT_IND | SI1: CPCM_IND | SJ1: OTHER_TOOL_TECH_IND | SK1: AXIAL_RECENT_YEAR | SL1: AXIAL_RCNT_PROPUL_METHOD | SM1: AXIAL_RCNT_ATTUNED_DETECT | SN1: AXIAL_RCNT_ATND_DTCT_DTLS | SO1: AXIAL_RCNT_ATND_DTCT_METAL | SP1: AXIAL_RCNT_ATT_DT_METAL_DTLS | SQ1: AXIAL_PREVIOUS_YEAR | SR1: AXIAL_PREV_PROPUL_METHOD | SS1: AXIAL_PREV_ATTUNED_DETECT | ST1: AXIAL_PREV_ATND_DTCT_DTLS | SU1: AXIAL_PREV_ATND_DTCT_METAL | SV1: AXIAL_PREV_ATT_DT_METAL_DTLS | SW1: CIRC_WAVE_RECENT_YEAR | SX1: CIRC_WV_RCNT_PROPUL_METHOD | SY1: CIRC_WV_RCNT_RESOLUTION | SZ1: CIRC_WV_RCNT_RESOLUTION_DTLS | TA1: CIRC_WV_PREVIOUS_YEAR | TB1: CIRC_WV_PREV_PROPUL_METHOD | TC1: CIRC_WV_PREV_RESOLUTION | TD1: CIRC_WV_PREV_RESOLUTION_DTLS | TE1: ULTRASONIC_RECENT_YEAR | TF1: ULTRASONIC_RCNT_PROPUL_METHOD | TG1: ULTRASONIC_RCNT_ATTUNED | TH1: ULTRA_RCNT_ATTUNEDD_DTLS | TI1: UTRA_RCNT_ATT_METL_RESOLUTION | TJ1: UTRA_RCNT_ATT_METL_RES_DTLS | TK1: ULTR_PREVIOUS_YEAR | TL1: ULTRA_PREV_PROPUL_METHOD | TM1: ULTRA_PREV_ATTUNED | TN1: ULTRA_PREV_ATTUNED_DTLS | TO1: UTRA_PREV_ATT_METL_RESOLUTION | TP1: UTRA_PREV_ATT_METL_RES_DTLS | TQ1: GEOMETRY_RECENT_YEAR | TR1: GEOMETRY_RCNT_PROPUL_METHOD | TS1: GEOMETRY_RCNT_RESOLUTION | TT1: GEOMETRY_RCNT_RESOLUTION_DTLS | TU1: GEOMETRT_RCNT_MEASUR_CUPS | TV1: GEOMETRY_PREVIOUS_YEAR | TW1: GEOMETRY_PREV_PROPUL_METHOD | TX1: GEOMETRY_PREV_RESOLUTION | TY1: GEOMETRY_PREV_RESOLUTION_DTLS | TZ1: GEOMETRT_PREV_MEASUR_CUPS | UA1: EMAT_RECENT_YEAR | UB1: EMAT_RCNT_PROPUL_METHOD | UC1: EMAT_PREVIOUS_YEAR | UD1: EMAT_PREV_PROPUL_METHOD | UE1: CPCM_RECENT_YEAR | UF1: CPCM_RCNT_PROPUL_METHOD | UG1: CPCM_PREVIOUS_YEAR | UH1: CPCM_PREV_PROPUL_METHOD | UI1: OTHER_TOOL | UJ1: OTHER_RECENT_YEAR | UK1: OTHER_RCNT_PROPUL_METHOD | UL1: OTHER_PREVIOUS_YEAR | UM1: OTHER_PREV_PROPUL_METHOD | UN1: INSP_COMPL_BEFORE_DAMAGE_IND | UO1: HAS_HYDRTST_CONDUC_BEFORE_IND | UP1: HYDRTST_MOST_RCNT_YEAR | UQ1: HYDRTST_MOST_RCNT_PRESSURE | UR1: DIRECT_ASMNT_CONDUCTED | US1: DIRECT_ASMNT_AT_PNT_ACCDNT_YR | UT1: DIRECT_ASMNT_PNT_NOT_IDNTF_YR | UU1: ASMNT_ECDA_RCNT_IND | UV1: ASMNT_ECDA_RCNT_YEAR | UW1: ASMNT_OTHER_RCNT_IND | UX1: ASMNT_OTHER_TYPE | UY1: ASMNT_OTHER_RCNT_YEAR | UZ1: NON_DESTRUCTIVE_EXAM_IND | VA1: EXM_RADIOGRAPHY_RCNT_YEAR | VB1: EXM_WAVE_ULTRASONIC_RCNT_YEAR | VC1: EXM_HANDL_ULTRASONIC_RCNT_YEAR | VD1: EXM_WET_MGNT_PARTCL_RCNT_YEAR | VE1: EXM_DRY_MGNT_PARTCL_RCNT_YEAR | VF1: EXM_OTHER_TYPE | VG1: EXM_OTHER_RCNT_YEAR | VH1: EXM_RADIOGRAPHY_RCNT_IND | VI1: EXM_WAVE_ULTRASONIC_RCNT_IND | VJ1: EXM_HANDL_ULTRASONIC_RCNT_IND | VK1: EXM_WET_MGNT_PARTCL_RCNT_IND | VL1: EXM_DRY_MGNT_PARTCL_RCNT_IND | VM1: EXM_OTHER_RCNT_IND | VN1: EXTRNL_COR_GALVANIC_IND | VO1: EXTRNL_COR_ATMOSPHERIC_IND | VP1: EXTRNL_COR_STRAY_CURRENT_IND | VQ1: EXTRNL_COR_MICROBIOLOGIC_IND | VR1: EXTRNL_COR_SELECTIVE_SEAM_IND | VS1: INTRNL_COR_CORROSIVE_CMDTY_IND | VT1: INTRNL_COR_WTR_DRPOUT_ACID_IND | VU1: INTRNL_COR_MICROBIOLOGIC_IND | VV1: INTRNL_COR_EROSION_IND | VW1: NF_EARTH_MOVEMENT_IND | VX1: NF_HEAVY_RAINS_IND | VY1: NF_LIGHTNING_IND | VZ1: NF_TEMPERATURE_IND | WA1: NF_HIGH_WINDS_IND | WB1: NF_VEGITATION_ROOT_IND | WC1: EXCVTN_DMG_OPERATOR_IND | WD1: EXCVTN_DMG_OP_CONTRACTOR_IND | WE1: EXCVTN_DMG_THIRD_PARTY_IND | WF1: EXCVTN_DMG_PREVIOUS_DAMAGE_IND | WG1: OSF_NEARBY_INDUSTRIAL_IND | WH1: OSF_VEHICLE_IND | WI1: OSF_BOAT_IND | WJ1: OSF_OTHER_MARITIME_IND | WK1: OSF_ELECTRICAL_ARCING_IND | WL1: OSF_PREVIOUS_MECHANICAL_IND | WM1: OSF_INTENTIONAL_IND | WN1: PWF_DESIGN_IND | WO1: PWF_CONSTRUCTION_IND | WP1: PWF_INSTALLATION_IND | WQ1: PWF_FABRICATION_IND | WR1: PWF_MANUFACTURING_IND | WS1: PWF_ENV_STRESS_CORROSION_IND | WT1: PWF_ENV_SULFIDE_STRESS_IND | WU1: PWF_ENV_HYDROGEN_STRESS_IND | WV1: PWF_ENV_HARD_SPOT_IND | WW1: EQF_CONTROL_RELEAF_IND | WX1: EQF_PUMP_EQUIPMENT_IND | WY1: EQF_THREADED_COUPLING_IND | WZ1: EQF_NON_THREADED_IND | XA1: EQF_DEFECTIVE_FITTING_IND | XB1: EQF_EQUIPMENT_BODY_IND | XC1: IO_DAMAGE_BY_OPERATOR_IND | XD1: IO_TANK_VESSEL_IND | XE1: IO_VALVE_POSITION_IND | XF1: IO_EQUIPMENT_OVERPRESSURE_IND | XG1: IO_NOT_INSTALLED_PROPERLY_IND | XH1: IO_WRONG_EQUIPMENT_IND | XI1: IO_INADEQUATE_PROCEDURE_IND | XJ1: IO_NO_PROCEDURE_IND | XK1: IO_FOLLOW_PROCEDURE_IND | XL1: PREPARER_NAME | XM1: PREPARER_TITLE | XN1: PREPARER_EMAIL | XO1: PREPARER_TELEPHONE | XP1: PREPARER_FAX | XQ1: PREPARED_DATE | XR1: LOCAL_CONTACT_NAME | XS1: LOCAL_CONTACT_EMAIL | XT1: LOCAL_CONTACT_TELEPHONE | XU1: AUTHORIZER_NAME | XV1: AUTHORIZER_TELEPHONE | XW1: AUTHORIZER_TITLE | XX1: AUTHORIZER_EMAIL | XY1: NARRATIVE
A2: 0 | B2: 45838 | C2: 2025 | D2: 20250158 | E2: 41089 | F2: ORIGINAL | G2: 39368 | H2: CRESTWOOD MIDSTREAM PARTNERS LP | I2: 1300 MAIN STREET | J2: HOUSTON | K2: TX | L2: 77002 | M2: 45814.733 | N2: CENTRAL | O2: YES | P2: 47.80288 | Q2: -102.8753 | R2: CRUDE OIL | W2: 0.1 | Y2: 0.1 | Z2: NO | AF2: 0 | AG2: NO | AM2: 0 | AN2: LOCAL OPERATING PERSONNEL, INCLUDING CONTRACTORS | AP2: OPERATOR EMPLOYEE | AQ2: 45814.733 | AR2: ONSHORE PUMP/METER STATION EQUIPMENT AND PIPING | AS2: ONSHORE | AT2: NORMAL OPERATION, INCLUDES PAUSES BETWEEN BATCHES AND DURING MAINTENANCE | AU2: YES | AW2: 45814.733 | AX2: 45815.326 | AZ2: NO | BC2: 45814.733 | BD2: 45814.733 | BE2: 45814.762 | BF2: 1433356 | BG2: 1433488 | BH2: YES | BI2: 45814.733 | BJ2: OPERATOR/CONTRACTOR | BL2: 0.1 | BM2: NO | BV2: YES | BW2: 45814.736 | BX2: NO | CA2: 0 | CB2: ARROW CENTRAL DELIVERY POINT | CC2: 8-INCH 100 LINE | CD2: ND | CE2: 58847 | CF2: Not Within a Municipality | CG2: MCKENZIE | CH2: SURVEY STATION NO. | CI2: 0+00 | CJ2: NO | CK2: TOTALLY CONTAINED ON OPERATOR-CONTROLLED PROPERTY | CL2: ABOVEGROUND | CM2: INSIDE A BUILDING | CP2: NO | DM2: INTRASTATE | DN2: PUMP | EQ2: CENTRIFUGAL | ES2: INJECTION | FK2: 2018 | FL2: 2018 | FM2: CARBON STEEL | FO2: LEAK | FR2: SEAL OR PACKING | FY2: NO | GC2: NO | GD2: NO | GE2: NO | GK2: NO | GT2: NO | GU2: NO | HF2: 0 | HG2: 5 | HH2: 25000 | HI2: 100 | HJ2: 0 | HK2: 0 | HM2: 25105 | HN2: 0 | HO2: 0 | HP2: 0 | HQ2: 0 | HR2: 256 | HS2: 740 | HT2: FOUR HOUR TEST OR OPERATION ß195.406(A)(5) | HV2: 42838 | HW2: NO | HY2: PRESSURE DID NOT EXCEED MOP | HZ2: NO | IS2: > 20% SMYS REGULATED TRANSMISSION | IT2: YES | IU2: YES | IV2: YES | IW2: YES | IX2: NO | IY2: YES | IZ2: YES | JA2: YES | JB2: NO | JC2: NO | JD2: NO, THE OPERATOR DID NOT FIND THAT AN INVESTIGATION OF THE CONTROLLER(S) ACTIONS OR CONTROL ROOM ISSUES WAS NECESSARY DUE TO: (PROVIDE AN EXPLANATION FOR WHY THE OPERATOR DID NOT INVESTIGATE) | JE2: A REVIEW OF THE ACCIDENT DETERMINED THAT THERE WERE NO CONTROL ROOM ACTIONS THAT CONTRIBUTED TO THE EVENT. | JR2: NO | JS2: NO | JX2: OTHER ACCIDENT CAUSE | JY2: UNKNOWN | RY2: UNKNOWN | SA2: STILL UNDER INVESTIGATION, CAUSE OF ACCIDENT TO BE DETERMINED* (*SUPPLEMENTAL REPORT REQUIRED) | XL2: TODD NARDOZZI | XM2: DIRECTOR - DOT COMPLIANCE | XN2: todd.nardozzi@energytransfer.com | XO2: 713-989-7126 | XQ2: 45838 | XU2: TODD NARDOZZI | XV2: 713-989-7126 | XW2: DIRECTOR - DOT COMPLIANCE | XX2: todd.nardozzi@energytransfer.com | XY2: ON 06/06/25 AT APPROXIMATELY 17:35, AN OPERATOR EMPLOYEE DISCOVERED A SMALL FIRE ON PUMP C3 IN THE PUMP ROOM. THE FIRE WAS IMMEDIATELY EXTINGUISHED WITH A FIRE EXTINGUISHER. OPERATIONS DISCOVERED CRUDE OIL LEAKING FROM A SEAL ON THE 8INCH 100 LINE INSIDE ARROW CENTRAL DELIVERY POINT (CDP). APPROXIMATELY 1 GALLON OF CRUDE OIL WAS RELEASED. A SMALL AMOUNT OF PRODUCT WAS CONSUMED BY THE FIRE. THE REMAINING PRODUCT WAS CLEANED-UP BY LOCAL PERSONNEL. THE PUMP WAS REMOVED AND FLANGES BLINDED. THE PUMP HAS BEEN SENT TO A THIRD PARTY FOR ANALYSIS, INSPECTION AND REPAIR. THE LINE WAS RESTARTED ON 06/07/25 AT 07:50. THE CAUSE OF THE ACCIDENT IS STILL UNDER INVESTIGATION BY A THIRD PARTY. A SUPPLEMENTAL REPORT WILL BE SUBMITTED ONCE THE INVESTIGATION IS COMPLETE.
A3: 5 | B3: 45824 | C3: 2025 | D3: 20250148 | E3: 41029 | F3: ORIGINAL | G3: 31476 | H3: ET CRUDE OPERATING LLC | I3: 1300 MAIN STREET | J3: HOUSTON | K3: TX | L3: 77002 | M3: 45800.635 | N3: CENTRAL | O3: YES | P3: 36.0175 | Q3: -96.753889 | R3: CRUDE OIL | W3: 80 | Y3: 80 | Z3: NO | AF3: 0 | AG3: NO | AM3: 0 | AN3: LOCAL OPERATING PERSONNEL, INCLUDING CONTRACTORS | AP3: OPERATOR EMPLOYEE | AQ3: 45800.635 | AR3: ONSHORE TERMINAL/TANK FARM EQUIPMENT AND PIPING | AS3: ONSHORE | AT3: NORMAL OPERATION, INCLUDES PAUSES BETWEEN BATCHES AND DURING MAINTENANCE | AU3: YES | AW3: 45800.635 | AY3: YES | AZ3: NO | BC3: 45800.635 | BD3: 45800.635 | BE3: 45800.665 | BF3: 1432002 | BG3: 1432157 | BH3: NO | BV3: YES | BW3: 45800.635 | BX3: YES | BY3: 45800.639 | BZ3: 45800.705 | CA3: 0 | CB3: CUSHING TANK FARM | CC3: CIMARRON LINE | CD3: OK | CE3: 74023 | CF3: Not Within a Municipality | CG3: PAYNE | CH3: SURVEY STATION NO. | CI3: 0+00 | CJ3: NO | CK3: TOTALLY CONTAINED ON OPERATOR-CONTROLLED PROPERTY | CL3: UNDERGROUND | CM3: UNDER SOIL | CO3: 42 | CP3: NO | DM3: INTERSTATE | DN3: PIPE | DO3: PIPE BODY | DP3: NO | DQ3: 8 | DR3: 0.312 | DS3: 35000 | DT3: GRADE B | DU3: ERW - HIGH FREQUENCY | DW3: UNKNOWN | DX3: FUSION BONDED EPOXY(FBE) | DZ3: NO | FK3: UNKNOWN | FL3: UNKNOWN | FM3: CARBON STEEL | FO3: LEAK | FR3: PINHOLE | FY3: NO | GC3: YES | GD3: NO | GE3: YES | GH3: YES | GK3: NO | GT3: NO | GU3: NO | HF3: 0 | HG3: 50 | HH3: 5000 | HI3: 60000 | HJ3: 30000 | HK3: 0 | HM3: 95050 | HN3: 0 | HO3: 0 | HP3: 0 | HQ3: 0 | HR3: 117 | HS3: 285 | HT3: COMPONENT DESIGN PRESSURE ß195.406(A)(2) | HV3: 42736 | HW3: NO | HY3: PRESSURE DID NOT EXCEED MOP | HZ3: NO | IS3: > 20% SMYS REGULATED TRANSMISSION | IT3: YES | IU3: YES | IV3: YES | IW3: NO | IX3: NO | IY3: NO | JD3: NO, THE OPERATOR DID NOT FIND THAT AN INVESTIGATION OF THE CONTROLLER(S) ACTIONS OR CONTROL ROOM ISSUES WAS NECESSARY DUE TO: (PROVIDE AN EXPLANATION FOR WHY THE OPERATOR DID NOT INVESTIGATE) | JE3: A REVIEW OF THE ACCIDENT DETERMINED THAT THERE WERE NO CONTROL ROOM ACTIONS THAT CONTRIBUTED TO THE EVENT. | JR3: NO | JS3: NO | JX3: OTHER ACCIDENT CAUSE | JY3: UNKNOWN | RY3: UNKNOWN | SA3: STILL UNDER INVESTIGATION, CAUSE OF ACCIDENT TO BE DETERMINED* (*SUPPLEMENTAL REPORT REQUIRED) | XL3: TODD NARDOZZI | XM3: DIRECTOR - DOT COMPLIANCE | XN3: todd.nardozzi@energytransfer.com | XO3: 713-989-7126 | XQ3: 45824 | XU3: TODD NARDOZZI | XV3: 713-989-7126 | XW3: DIRECTOR - DOT COMPLIANCE | XX3: todd.nardozzi@energytransfer.com | XY3: ON 05/23/25 AT 15:15, CRUDE OIL WAS DISCOVERED ON THE GROUND BENEATH STATION PIPING AT TANK 2538 CUSHING TANK FARM. THE LEAK WAS COMING FROM A PINHOLE AT THE 6 O'CLOCK POSITION ON THE CIMARRON 8-INCH LINE. APPROXIMATELY 80 BARRELS OF CRUDE OIL WAS RELEASED ON THE GROUND. CLEANUP CONTRACTORS REMOVED PRODUCT AND CONTAMINATED SOIL. THE LEAK WAS REPAIRED WITH A PLIDCO CLAMP. THE LINE WAS DRAINED, AND THE FAILED SECTION WAS CUT OUT AND SENT TO A THIRD PARTY LAB FOR ANALYSIS. THE LINE REMAINS SHUTDOWN. THE CAUSE OF THE LEAK IS STILL UNDER INVESTIGATION. A SUPPLEMENTAL REPORT WILL BE SUBMITTED ONCE THE LAB REPORT AND INVESTIGATION ARE COMPLETED.
A4: 7 | B4: 45826 | C4: 2025 | D4: 20250151 | E4: 41054 | F4: ORIGINAL | G4: 32099 | H4: ENERGY TRANSFER COMPANY | I4: 1300 MAIN STREET | J4: HOUSTON | K4: TX | L4: 77002 | M4: 45800.332 | N4: CENTRAL | O4: YES | P4: 32.00959 | Q4: -102.03685 | R4: CRUDE OIL | W4: 1 | Y4: 1 | Z4: NO | AF4: 0 | AG4: NO | AM4: 0 | AN4: LOCAL OPERATING PERSONNEL, INCLUDING CONTRACTORS | AP4: OPERATOR EMPLOYEE | AQ4: 45800.332 | AR4: ONSHORE TERMINAL/TANK FARM EQUIPMENT AND PIPING | AS4: ONSHORE | AT4: NORMAL OPERATION, INCLUDES PAUSES BETWEEN BATCHES AND DURING MAINTENANCE | AU4: YES | AW4: 45800.337 | AX4: 45800.626 | AZ4: YES | BA4: OPERATOR | BB4: 45800.383 | BC4: 45800.335 | BD4: 45800.347 | BF4: NRC NOTIFICATION NOT REQUIRED | BH4: NO | BV4: NO | BX4: NO | CA4: 0 | CB4: MIDLAND TANK FARM | CC4: 24INCH MIDLAND MESA C20017 | CD4: TX | CE4: 79706 | CF4: Not Within a Municipality | CG4: MIDLAND | CH4: SURVEY STATION NO. | CI4: 0+00 | CJ4: NO | CK4: TOTALLY CONTAINED ON OPERATOR-CONTROLLED PROPERTY | CL4: ABOVEGROUND | CM4: TYPICAL ABOVEGROUND FACILITY PIPING OR APPURTENANCE | CP4: NO | DM4: INTRASTATE | DN4: FLANGE ASSEMBLY | FK4: 2012 | FL4: 2012 | FM4: CARBON STEEL | FO4: LEAK | FR4: SEAL OR PACKING | FY4: NO | GC4: YES | GD4: NO | GE4: YES | GH4: YES | GK4: NO | GT4: NO | GU4: NO | HF4: 0 | HG4: 33 | HH4: 0 | HI4: 1955 | HJ4: 183 | HK4: 0 | HM4: 2171 | HN4: 0 | HO4: 0 | HP4: 0 | HQ4: 0 | HR4: 420 | HS4: 285 | HT4: COMPONENT DESIGN PRESSURE ß195.406(A)(2) | HV4: 41030 | HW4: NO | HY4: PRESSURE EXCEEDED 110% OF MOP | HZ4: NO | IS4: > 20% SMYS REGULATED TRANSMISSION | IT4: YES | IU4: YES | IV4: YES | IW4: NO | IX4: NO | IY4: NO | JD4: NO, THE OPERATOR DID NOT FIND THAT AN INVESTIGATION OF THE CONTROLLER(S) ACTIONS OR CONTROL ROOM ISSUES WAS NECESSARY DUE TO: (PROVIDE AN EXPLANATION FOR WHY THE OPERATOR DID NOT INVESTIGATE) | JE4: A REVIEW OF THE ACCIDENT DETERMINED THAT THERE WERE NO CONTROL ROOM ACTIONS THAT CONTRIBUTED TO THE EVENT. | JR4: YES | JS4: NO | JT4: 1 | JU4: 0 | JX4: OTHER ACCIDENT CAUSE | JY4: UNKNOWN | RY4: UNKNOWN | SA4: STILL UNDER INVESTIGATION, CAUSE OF ACCIDENT TO BE DETERMINED* (*SUPPLEMENTAL REPORT REQUIRED) | XL4: TODD NARDOZZI | XM4: DIRECTOR - DOT COMPLIANCE | XN4: todd.nardozzi@energytransfer.com | XO4: 713-989-7126 | XQ4: 45826 | XU4: TODD NARDOZZI | XV4: 713-989-7126 | XW4: DIRECTOR - DOT COMPLIANCE | XX4: todd.nardozzi@energytransfer.com | XY4: ON 05/23/25 AT APPROXIMATELY 07:58, A LOCAL OPERATOR EMPLOYEE CLOSED MOV 6001 CAUSING THE 24INCH MIDLAND MESA C20017 LINE TO OVERPRESSURE, WHICH LED TO A RELEASE OF CRUDE OIL ONTO THE GROUND. THE LINE WAS IMMEDIATELY SHUTDOWN AND ISOLATED. THE LEAK WAS DISCOVERED TO BE COMING FROM A FLANGE. FLANGES WERE RETORQUED TO STOP LEAK, THE LINE WAS INSPECTED VISUALLY AND WAS RETURNED TO SERVICE. APPROXIMATELY 1 BARREL OF CRUDE OIL WAS RELEASED. CLEANUP CONTRACTORS REMOVED PRODUCT AND REMEDIATED IMPACTED SOIL. THE CAUSE OF THE ACCIDENT IS STILL UNDER INVESTIGATION. A SUPPLEMENTAL REPORT WILL BE SUBMITTED ONCE COMPLETE.
A5: 10 | B5: 45824 | C5: 2025 | D5: 20250147 | E5: 41028 | F5: ORIGINAL | G5: 32099 | H5: ENERGY TRANSFER COMPANY | I5: 1300 MAIN STREET | J5: HOUSTON | K5: TX | L5: 77002 | M5: 45797.433 | N5: CENTRAL | O5: YES | P5: 32.3066 | Q5: -101.8971 | R5: CRUDE OIL | W5: 1 | Y5: 1 | Z5: NO | AF5: 0 | AG5: NO | AM5: 0 | AN5: LOCAL OPERATING PERSONNEL, INCLUDING CONTRACTORS | AP5: OPERATOR EMPLOYEE | AQ5: 45797.433 | AR5: ONSHORE PUMP/METER STATION EQUIPMENT AND PIPING | AS5: ONSHORE | AT5: NORMAL OPERATION, INCLUDES PAUSES BETWEEN BATCHES AND DURING MAINTENANCE | AU5: NO | AV5: UTILIZED OTHER LACTS TO CONTINUE FLOW | AZ5: YES | BA5: OPERATOR | BB5: 45800.361 | BC5: 45797.433 | BD5: 45797.433 | BF5: NRC NOTIFICATION NOT REQUIRED | BH5: NO | BV5: NO | BX5: NO | CA5: 0 | CB5: RC SMITH STATION | CC5: 23025 - 12INCH RC SMITH TO SUNOCO MIDLAND TERMINAL | CD5: TX | CE5: 79783 | CF5: Not Within a Municipality | CG5: MARTIN | CH5: SURVEY STATION NO. | CI5: 0+00 | CJ5: NO | CK5: TOTALLY CONTAINED ON OPERATOR-CONTROLLED PROPERTY | CL5: ABOVEGROUND | CM5: TYPICAL ABOVEGROUND FACILITY PIPING OR APPURTENANCE | CP5: NO | DM5: INTRASTATE | DN5: OTHER | FJ5: 1 INCH PIPE NIPPLE | FK5: 2013 | FL5: UNKNOWN | FM5: CARBON STEEL | FO5: LEAK | FR5: CRACK | FY5: NO | GC5: YES | GD5: NO | GE5: YES | GH5: YES | GK5: NO | GT5: NO | GU5: NO | HF5: 0 | HG5: 80 | HH5: 3500 | HI5: 180 | HJ5: 1000 | HK5: 0 | HM5: 4760 | HN5: 0 | HO5: 0 | HP5: 0 | HQ5: 0 | HR5: 325 | HS5: 1480 | HT5: COMPONENT DESIGN PRESSURE ß195.406(A)(2) | HV5: 41548 | HW5: NO | HY5: PRESSURE DID NOT EXCEED MOP | HZ5: NO | IS5: > 20% SMYS REGULATED TRANSMISSION | IT5: YES | IU5: YES | IV5: YES | IW5: NO | IX5: NO | IY5: YES | IZ5: YES | JA5: YES | JB5: NO | JC5: NO | JD5: NO, THE OPERATOR DID NOT FIND THAT AN INVESTIGATION OF THE CONTROLLER(S) ACTIONS OR CONTROL ROOM ISSUES WAS NECESSARY DUE TO: (PROVIDE AN EXPLANATION FOR WHY THE OPERATOR DID NOT INVESTIGATE) | JE5: A REVIEW OF THE ACCIDENT DETERMINED THAT THERE WERE NO CONTROL ROOM ACTIONS THAT CONTRIBUTED TO THE EVENT. | JR5: NO | JS5: NO | JX5: OTHER ACCIDENT CAUSE | JY5: UNKNOWN | RY5: UNKNOWN | SA5: STILL UNDER INVESTIGATION, CAUSE OF ACCIDENT TO BE DETERMINED* (*SUPPLEMENTAL REPORT REQUIRED) | XL5: TODD NARDOZZI | XM5: DIRECTOR - DOT COMPLIANCE | XN5: todd.nardozzi@energytransfer.com | XO5: 713-989-7126 | XQ5: 45824 | XU5: TODD NARDOZZI | XV5: 713-989-7126 | XW5: DIRECTOR - DOT COMPLIANCE | XX5: todd.nardozzi@energytransfer.com | XY5: ON 05/20/2025 AT APPROXIMATELY 10:23, A MEASUREMENT SPECIALIST REPORTED A RELEASE AT RC SMITH STATION. DISCOVERED LEAK FROM CRACKED NIPPLE ON THE PUMP SIDE OF 23025 - 12INCH RC SMITH TO SUNOCO MIDLAND TERMINAL. APPROXIMATELY 1 BARREL OF CRUDE OIL WAS RELEASED. CLEANUP CONTRACTORS REMOVED PRODUCT AND REMEDIATED IMPACTED SOIL. REPAIRED LEAK BY REPLACING FAILED NIPPLE. THE CAUSE OF THE ACCIDENT IS STILL UNDER INVESTIGATION. A SUPPLEMENTAL REPORT WILL BE SUBMITTED ONCE THE INVESTIGATION IS COMPLETE.
A6: 18 | B6: 45793 | C6: 2025 | D6: 20250124 | E6: 40896 | F6: ORIGINAL | G6: 10012 | H6: NUSTAR PIPELINE OPERATING PARTNERSHIP L.P. | I6: 8111 WESTCHESTER DRIVE | J6: DALLAS | K6: TX | L6: 75225 | M6: 45785.897 | N6: CENTRAL | O6: YES | P6: 35.0248 | Q6: -91.9321 | R6: HVL OR OTHER FLAMMABLE OR TOXIC FLUID WHICH IS A GAS AT AMBIENT CONDITIONS | S6: ANHYDROUS AMMONIA | W6: 1 | X6: 0 | Y6: 0 | Z6: NO | AF6: 0 | AG6: NO | AM6: 0 | AN6: NOTIFICATION FROM PUBLIC | AQ6: 45785.897 | AR6: ONSHORE PIPELINE, INCLUDING VALVE SITES | AS6: ONSHORE | AT6: NORMAL OPERATION, INCLUDES PAUSES BETWEEN BATCHES AND DURING MAINTENANCE | AU6: YES | AW6: 45785.927 | AX6: 45786.781 | AZ6: NO | BC6: 45785.878 | BD6: 45785.897 | BE6: 45785.93 | BF6: 1430608 | BG6: NO | BH6: NO | BN6: VALVE CLOSURE | BP6: 45785.985 | BQ6: AUTOMATIC | BR6: VALVE CLOSURE | BT6: 45785.987 | BU6: MANUAL | CA6: 0 | CB6: NUSTAR AMMONIA SYSTEM - CABOT STA. TO FLORAL STA. | CC6: CABOT STATION - 10" TO FLORAL STATION | CD6: AR | CE6: 72176 | CF6: Not Within a Municipality | CG6: LONOKE | CH6: MILEPOST | CI6: 146 | CJ6: NO | CK6: PIPELINE RIGHT-OF-WAY | CL6: UNDERGROUND | CM6: UNDER SOIL | CO6: 48 | CP6: NO | DM6: INTERSTATE | DN6: TAP FITTING(STOPPLE, THREAD-O-RING, WELD-O-LET, ETC.) | FK6: 1997 | FL6: UNKNOWN | FM6: CARBON STEEL | FO6: LEAK | FR6: CRACK | FY6: NO | GC6: NO | GD6: NO | GE6: NO | GK6: NO | GT6: YES | GU6: YES | GZ6: YES | HA6: YES | HD6: YES | HE6: YES | HF6: 0 | HG6: 60 | HH6: 10000 | HI6: 0 | HJ6: 0 | HK6: 0 | HM6: 10060 | HN6: 0 | HO6: 0 | HP6: 0 | HQ6: 0 | HR6: 700 | HS6: 1340 | HT6: SUBPART E PRESSURE TEST ß195.406(A)(3) | HV6: 25305 | HW6: NO | HY6: PRESSURE DID NOT EXCEED MOP | HZ6: NO | IC6: 36700 | ID6: YES | IL6: NO | IS6: > 20% SMYS REGULATED TRANSMISSION | IT6: YES | IU6: YES | IV6: YES | IW6: NO | IX6: NO | IY6: YES | IZ6: YES | JA6: YES | JB6: NO | JC6: NO | JD6: NO, THE OPERATOR DID NOT FIND THAT AN INVESTIGATION OF THE CONTROLLER(S) ACTIONS OR CONTROL ROOM ISSUES WAS NECESSARY DUE TO: (PROVIDE AN EXPLANATION FOR WHY THE OPERATOR DID NOT INVESTIGATE) | JE6: THE CRACK IN THE PIPE WAS SMALL ENOUGH IT RENDERED THE LEAK UN-DETECTABLE BY THE CONTROL ROOM (SCADA/CPM). | JR6: NO | JS6: NO | JX6: EQUIPMENT FAILURE | JY6: MALFUNCTION OF CONTROL/RELIEF EQUIPMENT | QB6: MALFUNCTION OF CONTROL/RELIEF EQUIPMENT | QK6: YES | RK6: YES | RL6: SIDE SEAM WELD ON STOPPLE TEE. | XL6: DOUG STUCKY | XM6: MANAGER - PIPELINE SAFETY | XN6: doug.stucky@sunoco.com | XO6: 3162459695 | XQ6: 45793 | XR6: DOUG STUCKY | XS6: doug.stucky@sunoco.com | XT6: 3162459695 | XU6: DOUG STUCKY | XV6: 3162459695 | XW6: MANAGER - PIPELINE SAFETY | XX6: doug.stucky@sunoco.com | XY6: AT APPROXIMATELY 20:00 ON 08MAY25, SUNOCO / NUSTAR LOCAL PERSONNEL RECEIVED A CALL FROM A LANDOWNER THAT THEY SMELLED AMMONIA ANHYDROUS. LOCAL PERSONNEL DISPATCHED TO THE SITE, ARRIVING AT APPROXIMATELY 21:05 TO BEGIN WALKING THE LINE AND LOOKING FOR A LEAK. THE LEAK WAS CONFIRMED AT 21:32 WITH A CALL TO AMMONIA SYSTEM LEADERSHIP. SUNOCO / NUSTAR PIPELINE SAFETY PERSONNEL WERE NOTIFIED OF THE RELEASE AT 22:01 TO BEGIN THE NOTIFICATION PROCESS WITH THE NATIONAL RESPONSE CENTER (NRC). A CALL WAS PLACED AND RECEIVED BY THE NRC AT 22:19. MR. DAVIS TOOK THE CALL AND PROVIDED INCIDENT NUMBER 1430608. A FOLLOW-UP CALL WAS RECEIVED BY REGION 6 EPA AT 23:06 REQUESTING AN UPDATE ON THE INCIDENT AND AN OFFER TO PROVIDE ASSISTANCE, IF NEEDED. A SMALL VAPOR STREAM WAS IDENTIFIED COMING FROM THE UPSTREAM SIDE OF VALVE 3-27. CONTROL CENTER PERSONNEL WERE NOTIFIED OF THE RELEASE AND ASKED TO SHUT DOWN THE PIPELINE (22:15). LOCAL PERSONNEL WERE DISPATCHED TO CLOSE THE UPSTREAM VALVE (3-25) AND THE DOWNSTREAM VALVE (3-27). LOCAL PERSONNEL PROVIDED OVERNIGHT AIR MONITORING OF THE SITE. VISQUEEN WAS USED TO COVER THE LEAK AND KEEP THE VAPORS DOWN. THERE WAS NO DANGER TO LOCAL RESIDENTS AND NO NOTIFICATIONS WERE MADE TO LOCAL AUTHORITIES. SUNOCO / NUSTAR MAINTENANCE PERSONNEL WERE CALLED AND DISPATCHED TO THE SITE FOR REPAIRS. UPON EXCAVATION OF THE VALVE SITE, A SMALL CRACK WAS DISCOVERED ON THE SIDE SEAM WELD OF A STOPPLE TEE. REPAIRS WERE COMPLETED AND THE LINE WAS RETURNED TO SERVICE AT 18:45 ON 09MAY25.
A7: 23 | B7: 45813 | C7: 2025 | D7: 20250139 | E7: 40994 | F7: ORIGINAL | G7: 39596 | H7: PERMIAN EXPRESS PARTNERS LLC | I7: 1300 MAIN STREET | J7: HOUSTON | K7: TX | L7: 77002 | M7: 45782.266 | N7: CENTRAL | O7: YES | P7: 32.728841 | Q7: -97.189752 | R7: CRUDE OIL | W7: 6600 | Y7: 6600 | Z7: NO | AF7: 0 | AG7: NO | AM7: 0 | AN7: SCADA-BASED INFORMATION (SUCH AS ALARM(S), ALERT(S), EVENT(S), AND/OR VOLUME OR PACK CALCULATIONS) | AQ7: 45782.266 | AR7: ONSHORE PIPELINE, INCLUDING VALVE SITES | AS7: ONSHORE | AT7: NORMAL OPERATION, INCLUDES PAUSES BETWEEN BATCHES AND DURING MAINTENANCE | AU7: YES | AW7: 45782.267 | AX7: 45786.917 | AZ7: NO | BC7: 45783.588 | BD7: 45783.59 | BE7: 45783.631 | BF7: 1430396 | BG7: 1430457 | BH7: NO | BN7: VALVE CLOSURE | BP7: 45782.269 | BQ7: REMOTELY CONTROLLED | BR7: VALVE CLOSURE | BT7: 45782.271 | BU7: REMOTELY CONTROLLED | BV7: YES | BW7: 45783.588 | BX7: YES | BY7: 45783.625 | BZ7: 45783.75 | CA7: 0 | CB7: RINGGOLD TO CORSICANA | CC7: 22002.01 - 16INCH CORSICANA TO KELLER | CD7: TX | CE7: 76013 | CF7: ARLINGTON | CG7: TARRANT | CH7: MILEPOST | CI7: 90.82 | CJ7: NO | CK7: PIPELINE RIGHT-OF-WAY | CL7: UNDERGROUND | CM7: UNDER SOIL | CO7: 64 | CP7: NO | DM7: INTERSTATE | DN7: PIPE | DO7: PIPE BODY | DP7: NO | DQ7: 16 | DR7: 0.25 | DS7: 42000 | DT7: API-5L X-42 | DU7: ERW - LOW FREQUENCY | DW7: UNKNOWN | DX7: COAL TAR | DZ7: UNKNOWN | FK7: 1953 | FL7: UNKNOWN | FM7: CARBON STEEL | FO7: LEAK | FR7: OTHER | FS7: STILL UNDER INVESTIGATION | FY7: NO | GC7: YES | GD7: NO | GE7: YES | GH7: YES | GK7: NO | GT7: YES | GU7: YES | GX7: YES | GY7: YES | HF7: 7600000 | HG7: 0 | HH7: 1000000 | HI7: 100000 | HJ7: 2000 | HK7: 0 | HM7: 8702000 | HN7: 0 | HO7: 0 | HP7: 0 | HQ7: 0 | HR7: 773 | HS7: 811 | HT7: SUBPART E PRESSURE TEST ß195.406(A)(3) | HV7: 35796 | HW7: NO | HY7: PRESSURE DID NOT EXCEED MOP | HZ7: NO | IC7: 120331 | ID7: YES | IL7: NO | IS7: > 20% SMYS REGULATED TRANSMISSION | IT7: YES | IU7: YES | IV7: YES | IW7: YES | IX7: YES | IY7: YES | IZ7: YES | JA7: YES | JB7: YES | JC7: YES | JD7: NO, THE OPERATOR DID NOT FIND THAT AN INVESTIGATION OF THE CONTROLLER(S) ACTIONS OR CONTROL ROOM ISSUES WAS NECESSARY DUE TO: (PROVIDE AN EXPLANATION FOR WHY THE OPERATOR DID NOT INVESTIGATE) | JE7: A REVIEW OF THE ACCIDENT DETERMINED THAT THERE WERE NO CONTROL ROOM ACTIONS THAT CONTRIBUTED TO THE EVENT. | JR7: NO | JS7: NO | JX7: OTHER ACCIDENT CAUSE | JY7: UNKNOWN | RY7: UNKNOWN | SA7: STILL UNDER INVESTIGATION, CAUSE OF ACCIDENT TO BE DETERMINED* (*SUPPLEMENTAL REPORT REQUIRED) | XL7: TODD NARDOZZI | XM7: DIRECTOR - DOT COMPLIANCE | XN7: todd.nardozzi@energytransfer.com | XO7: 713-989-7126 | XQ7: 45813 | XU7: TODD NARDOZZI | XV7: 713-989-7126 | XW7: DIRECTOR - DOT COMPLIANCE | XX7: todd.nardozzi@energytransfer.com | XY7: ON 05/05/2025 AT APPROXIMATELY 06:23, THE CONTROL CENTER RECEIVED SCADA INDICATIONS OF A RELEASE ON THE KELLER TO MIDLOTHIAN SEGMENT OF THE 16-INCH RINGGOLD TO CORSICANA SYSTEM. THE LINE WAS SHUTDOWN AND UPSTREAM AND DOWNSTREAM VALVES CLOSED TO ISOLATE THE SEGMENT. OPERATIONS PERSONNEL WERE DISPATCHED AND BEGAN FIELD INVESTIGATIONS TO LOCATE A POTENTIAL RELEASE. ON 05/06/2025 AT APPROXIMATELY 14:10, FIELD PERSONNEL DISCOVERED CRUDE OIL ON THE GROUND NEAR MP 90.82 IN THE ARLINGTON/FT. WORTH AREA. ONCE EXCAVATED, BOTH CRUDE OIL AND SEWER WATER WERE DISCOVERED IN THE EXCAVATION. THE LOCATION OF THE LEAK WAS WHERE A 48-INCH CITY OF FORT WORTH SEWER LINE CROSSED UNDER THE KELLER TO MIDLOTHIAN SEGMENT. INVESTIGATION IN THE DITCH FOUND THE CONCRETE SEWER LINE APPEARED TO HAVE FAILED AND WAS EXPELLING SEWAGE INTO THE THE IMMEDIATE AREA IN AND AROUND THE KELLER TO MIDLOTHIAN PIPELINE. APPROXIMATELY 6,600 BARRELS OF CRUDE OIL WAS RELEASED. THE MAJORITY OF THE RELEASED CRUDE TRAVELED THROUGH THE FAILED SEWER PIPE TO A WATER TREATMENT FACILITY APPROXIMATELY 4 MILES TO THE NORTHEAST. CLEANUP CONTRACTORS WERE MOBILIZED TO CLEANUP PRODUCT AND REMOVE IMPACTED SOIL AT THE FAILURE SITE. PEP COORDINATED CLEANUP EFFORTS AT THE WATER TREATMENT FACILITY WITH THE CITY. THE LINE WAS RESTARTED ON 5/9/25 AT 22:00 BY AFFECTING A STOPPLE AND BYPASS AROUND THE FAILED SECTION. AFTER THE PIPELINE WAS RESTARTED THE FAILED SECTION WAS COLD CUT AND REMOVED FROM THE GROUND, PREPPED AND SHIPPED TO A 3RD PARTY LABORATORY FOR ANALYSIS. THE CAUSE OF THE ACCIDENT IS STILL UNDER INVESTIGATION. A SUPPLEMENTAL REPORT WILL BE SUBMITTED ONCE COMPLETE.
A8: 38 | B8: 45789 | C8: 2025 | D8: 20250119 | E8: 40879 | F8: ORIGINAL | G8: 31476 | H8: ET CRUDE OPERATING LLC | I8: 1300 MAIN STREET | J8: HOUSTON | K8: TX | L8: 77002 | M8: 45762.319 | N8: CENTRAL | O8: YES | P8: 36.017432 | Q8: -96.75399 | R8: CRUDE OIL | W8: 8 | Y8: 8 | Z8: NO | AF8: 0 | AG8: NO | AM8: 0 | AN8: LOCAL OPERATING PERSONNEL, INCLUDING CONTRACTORS | AP8: OPERATOR EMPLOYEE | AQ8: 45762.319 | AR8: ONSHORE TERMINAL/TANK FARM EQUIPMENT AND PIPING | AS8: ONSHORE | AT8: NORMAL OPERATION, INCLUDES PAUSES BETWEEN BATCHES AND DURING MAINTENANCE | AU8: YES | AW8: 45762.319 | AX8: 45762.705 | AZ8: NO | BC8: 45762.319 | BD8: 45762.319 | BF8: NRC NOTIFICATION NOT REQUIRED | BH8: NO | BV8: YES | BW8: 45762.319 | BX8: NO | CA8: 0 | CB8: CUSHING TANK FARM | CC8: CIMARRON LINE | CD8: OK | CE8: 74023 | CF8: Not Within a Municipality | CG8: PAYNE | CH8: SURVEY STATION NO. | CI8: 0+00 | CJ8: NO | CK8: TOTALLY CONTAINED ON OPERATOR-CONTROLLED PROPERTY | CL8: UNDERGROUND | CM8: UNDER SOIL | CO8: 42 | CP8: NO | DM8: INTERSTATE | DN8: PIPE | DO8: PIPE BODY | DP8: NO | DQ8: 8 | DR8: 0.312 | DS8: 35000 | DT8: GRADE B | DU8: ERW - HIGH FREQUENCY | DW8: UNKNOWN | DX8: FUSION BONDED EPOXY(FBE) | DZ8: NO | FK8: UNKNOWN | FL8: UNKNOWN | FM8: CARBON STEEL | FO8: LEAK | FR8: PINHOLE | FY8: NO | GC8: YES | GD8: NO | GE8: YES | GH8: YES | GK8: NO | GT8: NO | GU8: NO | HF8: 0 | HG8: 30 | HH8: 6800 | HI8: 24836 | HJ8: 18036 | HK8: 0 | HM8: 49702 | HN8: 0 | HO8: 0 | HP8: 0 | HQ8: 0 | HR8: 117 | HS8: 285 | HT8: COMPONENT DESIGN PRESSURE ß195.406(A)(2) | HV8: 42736 | HW8: NO | HY8: PRESSURE DID NOT EXCEED MOP | HZ8: NO | IS8: < 20% SMYS REGULATED TRANSMISSION | IT8: YES | IU8: YES | IV8: YES | IW8: NO | IX8: NO | IY8: NO | JD8: NO, THE OPERATOR DID NOT FIND THAT AN INVESTIGATION OF THE CONTROLLER(S) ACTIONS OR CONTROL ROOM ISSUES WAS NECESSARY DUE TO: (PROVIDE AN EXPLANATION FOR WHY THE OPERATOR DID NOT INVESTIGATE) | JE8: A REVIEW OF THE ACCIDENT DETERMINED THAT THERE WERE NO CONTROL ROOM ACTIONS THAT CONTRIBUTED TO THE EVENT. | JR8: NO | JS8: NO | JX8: OTHER ACCIDENT CAUSE | JY8: UNKNOWN | RY8: UNKNOWN | SA8: STILL UNDER INVESTIGATION, CAUSE OF ACCIDENT TO BE DETERMINED* (*SUPPLEMENTAL REPORT REQUIRED) | XL8: TODD NARDOZZI | XM8: DIRECTOR - DOT COMPLIANCE | XN8: todd.nardozzi@energytransfer.com | XO8: 713-989-7126 | XQ8: 45789 | XU8: TODD NARDOZZI | XV8: 713-989-7126 | XW8: DIRECTOR - DOT COMPLIANCE | XX8: todd.nardozzi@energytransfer.com | XY8: ON 04/15/25 AT 07:40, CRUDE OIL WAS DISCOVERED ON THE GROUND BENEATH STATION PIPING AT TANK 2538 CUSHING TANK FARM. THE LEAK WAS COMING FROM A PINHOLE AT THE 6 O'CLOCK POSITION ON THE CIMARRON 8-INCH LINE. APPROXIMATELY 8 BARRELS OF CRUDE OIL WAS RELEASED ON THE GROUND. CLEANUP CONTRACTORS REMOVED PRODUCT AND CONTAMINATED SOIL. THE PIPE WAS TEMPORARILY REPAIRED WITH A PLIDCO CLAMP. THE CAUSE OF THE LEAK IS STILL UNDER INVESTIGATION. A SUPPLEMENTAL REPORT WILL BE SUBMITTED ONCE THE INVESTIGATION IS COMPLETE.
A9: 40 | B9: 45789 | C9: 2025 | D9: 20250120 | E9: 40880 | F9: ORIGINAL | G9: 32099 | H9: ENERGY TRANSFER COMPANY | I9: 1300 MAIN STREET | J9: HOUSTON | K9: TX | L9: 77002 | M9: 45760.351 | N9: CENTRAL | O9: YES | P9: 34.813972 | Q9: -97.711528 | R9: CRUDE OIL | W9: 5 | Y9: 5 | Z9: NO | AF9: 0 | AG9: NO | AM9: 0 | AN9: NOTIFICATION FROM PUBLIC | AQ9: 45760.351 | AR9: ONSHORE PIPELINE, INCLUDING VALVE SITES | AS9: ONSHORE | AT9: NORMAL OPERATION, INCLUDES PAUSES BETWEEN BATCHES AND DURING MAINTENANCE | AU9: YES | AW9: 45760.362 | AX9: 45760.595 | AZ9: NO | BC9: 45760.351 | BD9: 45760.396 | BF9: NRC NOTIFICATION NOT REQUIRED | BH9: NO | BN9: VALVE CLOSURE | BP9: 45760.382 | BQ9: MANUAL | BR9: VALVE CLOSURE | BT9: 45760.396 | BU9: MANUAL | BV9: YES | BW9: 45760.356 | BX9: NO | CA9: 0 | CB9: VELOCITY VLC-3 | CC9: NAPLES TO BRADLEY 8-INCH | CD9: OK | CE9: 73011 | CF9: Not Within a Municipality | CG9: GRADY | CH9: SURVEY STATION NO. | CI9: 1172+10 | CJ9: NO | CK9: PIPELINE RIGHT-OF-WAY | CL9: UNDERGROUND | CM9: UNDER SOIL | CO9: 50 | CP9: NO | DM9: INTRASTATE | DN9: PIPE | DO9: PIPE BODY | DP9: NO | DQ9: 8 | DR9: 0.188 | DS9: 52000 | DT9: API-5L X-52 | DU9: ERW - HIGH FREQUENCY | DW9: TEX-TUBE CO | DX9: FUSION BONDED EPOXY(FBE) | DZ9: NO | FK9: 2015 | FL9: UNKNOWN | FM9: CARBON STEEL | FO9: LEAK | FR9: PINHOLE | FY9: NO | GC9: YES | GD9: NO | GE9: YES | GH9: YES | GK9: NO | GT9: NO | GU9: NO | HF9: 2000 | HG9: 0 | HH9: 2500 | HI9: 5800 | HJ9: 20000 | HK9: 0 | HM9: 30300 | HN9: 0 | HO9: 0 | HP9: 0 | HQ9: 0 | HR9: 20 | HS9: 1440 | HT9: SUBPART E PRESSURE TEST ß195.406(A)(3) | HV9: 42192 | HW9: NO | HY9: PRESSURE DID NOT EXCEED MOP | HZ9: NO | IC9: 54338 | ID9: YES | IL9: NO | IS9: > 20% SMYS REGULATED TRANSMISSION | IT9: YES | IU9: YES | IV9: YES | IW9: NO | IX9: NO | IY9: NO | JD9: NO, THE OPERATOR DID NOT FIND THAT AN INVESTIGATION OF THE CONTROLLER(S) ACTIONS OR CONTROL ROOM ISSUES WAS NECESSARY DUE TO: (PROVIDE AN EXPLANATION FOR WHY THE OPERATOR DID NOT INVESTIGATE) | JE9: A REVIEW OF THE ACCIDENT DETERMINED THAT THERE WERE NO CONTROL ROOM ACTIONS THAT CONTRIBUTED TO THE EVENT. | JR9: NO | JS9: NO | JX9: OTHER ACCIDENT CAUSE | JY9: UNKNOWN | RY9: UNKNOWN | SA9: STILL UNDER INVESTIGATION, CAUSE OF ACCIDENT TO BE DETERMINED* (*SUPPLEMENTAL REPORT REQUIRED) | XL9: TODD NARDOZZI | XM9: DIRECTOR - DOT COMPLIANCE | XN9: todd.nardozzi@energytransfer.com | XO9: 713-989-7126 | XQ9: 45789 | XU9: TODD NARDOZZI | XV9: 713-989-7126 | XW9: DIRECTOR - DOT COMPLIANCE | XX9: todd.nardozzi@energytransfer.com | XY9: ON 04/13/25 AT APPROXIMATELY 08:00, THE ENERGY TRANSFER CONTROL CENTER RECEIVED A CALL FROM A LANDOWNER STATING OIL WAS OBSERVED ON THE ROW NEAR THE VLC-3 NAPLES TO BRADLEY 8-INCH LINE. THE PIPELINE WAS SHUT DOWN AND SECURED. PIPELINE TECHNICIANS WERE DISPATCHED TO CONFIRM THE PIPELINE RELEASE. ONCE THE PIPE WAS EXPOSED, THE LEAK WAS CONFIRMED TO BE COMING FROM A PINHOLE ON THE BOTTOM OF THE VLC-3 NAPLES TO BRADLEY 8-INCH LINE. APPROXIMATELY 5 BARRELS OF CRUDE OIL WAS RELEASED. CONTRACTORS CLEANED UP RELEASED PRODUCT AND CONTAMINATED SOIL. A CLAMP WAS INSTALLED TO PREVENT ANY FURTHER RELEASE. THE ACCIDENT IS STILL UNDER INVESTIGATION. A SUPPLEMENTAL REPORT WILL BE SUBMITTED ONCE THE ROOT CAUSE FAILURE ANALYSIS IS COMPLETED.
A10: 45 | B10: 45782 | C10: 2025 | D10: 20250111 | E10: 40846 | F10: ORIGINAL | G10: 39706 | H10: ENERGY TRANSFER NEDERLAND TERMINAL LLC | I10: 1300 MAIN STREET | J10: HOUSTON | K10: TX | L10: 77002 | M10: 45756.632 | N10: CENTRAL | O10: YES | P10: 30.000608 | Q10: -93.992447 | R10: CRUDE OIL | W10: 60 | Y10: 60 | Z10: NO | AF10: 0 | AG10: NO | AM10: 0 | AN10: LOCAL OPERATING PERSONNEL, INCLUDING CONTRACTORS | AP10: OPERATOR EMPLOYEE | AQ10: 45756.632 | AR10: ONSHORE TERMINAL/TANK FARM EQUIPMENT AND PIPING | AS10: ONSHORE | AT10: NORMAL OPERATION, INCLUDES PAUSES BETWEEN BATCHES AND DURING MAINTENANCE | AU10: YES | AW10: 45756.637 | AX10: 45761.667 | AZ10: NO | BC10: 45756.632 | BD10: 45756.632 | BE10: 45756.662 | BF10: 1428163 | BG10: 1428345 | BH10: NO | BV10: YES | BW10: 45756.633 | BX10: NO | CA10: 0 | CB10: NEDERLAND TERMINAL | CC10: MARSHLAND MANIFOLD | CD10: TX | CE10: 77627 | CF10: NEDERLAND | CG10: JEFFERSON | CH10: SURVEY STATION NO. | CI10: 0+00 | CJ10: NO | CK10: TOTALLY CONTAINED ON OPERATOR-CONTROLLED PROPERTY | CL10: ABOVEGROUND | CM10: TYPICAL ABOVEGROUND FACILITY PIPING OR APPURTENANCE | CP10: NO | DM10: INTERSTATE | DN10: RELIEF LINE AND RELIEF EQUIPMENT | FK10: 2019 | FL10: 2019 | FM10: CARBON STEEL | FO10: LEAK | FR10: CONNECTION FAILURE | FY10: NO | GC10: YES | GD10: NO | GE10: NO | GK10: NO | GT10: YES | GU10: YES | GX10: YES | GY10: YES | HF10: 0 | HG10: 4000 | HH10: 5000 | HI10: 20000 | HJ10: 95000 | HK10: 0 | HM10: 124000 | HN10: 0 | HO10: 0 | HP10: 0 | HQ10: 0 | HR10: 119 | HS10: 285 | HT10: COMPONENT DESIGN PRESSURE ß195.406(A)(2) | HV10: 40179 | HW10: NO | HY10: PRESSURE DID NOT EXCEED MOP | HZ10: NO | IS10: > 20% SMYS REGULATED TRANSMISSION | IT10: YES | IU10: YES | IV10: YES | IW10: NO | IX10: NO | IY10: YES | IZ10: YES | JA10: YES | JB10: NO | JC10: NO | JD10: NO, THE OPERATOR DID NOT FIND THAT AN INVESTIGATION OF THE CONTROLLER(S) ACTIONS OR CONTROL ROOM ISSUES WAS NECESSARY DUE TO: (PROVIDE AN EXPLANATION FOR WHY THE OPERATOR DID NOT INVESTIGATE) | JE10: A REVIEW OF THE ACCIDENT DETERMINED THAT THERE WERE NO CONTROL ROOM ACTIONS THAT CONTRIBUTED TO THE EVENT. | JR10: NO | JS10: NO | JX10: OTHER ACCIDENT CAUSE | JY10: UNKNOWN | RY10: UNKNOWN | SA10: STILL UNDER INVESTIGATION, CAUSE OF ACCIDENT TO BE DETERMINED* (*SUPPLEMENTAL REPORT REQUIRED) | XL10: TODD NARDOZZI | XM10: DIRECTOR - DOT COMPLIANCE | XN10: todd.nardozzi@energytransfer.com | XO10: 713-989-7126 | XQ10: 45782 | XU10: TODD NARDOZZI | XV10: 713-989-7126 | XW10: DIRECTOR - DOT COMPLIANCE | XX10: todd.nardozzi@energytransfer.com | XY10: ON 04/09/25 AT APPROXIMATELY 15:10, AN OPERATOR NOTIFIED MANAGEMENT THAT CRUDE OIL WAS FOUND LEAKING FROM THE #4 SHIP DOCK LINE. THE TRANSFER THROUGH THAT PIPE WAS STOPPED AND THE TRANSFER WAS MOVED TO ANOTHER PIPE TO CONTINUE THE TRANSFER. THE LEAK WAS COMING FROM A 1-INCH PIPE NIPPLE COMING OFF OF THE MAIN HEADER THAT HAD BROKEN OFF APPROXIMATELY 3-INCH ABOVE THE HEADER PIPE AT THE VALVE. APPROXIMATELY 60 BARRELS OF CRUDE OIL WAS RELEASED INTO CONTAINMENT. VACUUM TRUCKS AND CLEANUP PERSONNEL RESPONDED TO THE SITE FOR CLEANUP. ON 04/14/25 THE LEAK WAS REPAIRED BY INSTALLING AND HOT TAPPING NEW TORS WITH NEW 2-INCH VALVES. UTILIZED NEW PIPING AND RECONFIGURED THE LOCATION OF THE PRESSURE RELIEF VALVE WITH NEW SUPPORTS. THE CAUSE OF THE LEAK IS STILL UNDER INVESTIGATION. A SUPPLEMENTAL REPORT WILL BE SUBMITTED ONCE THE INVESTIGATION IS COMPLETE. TO PREVENT REOCCURRENCE, PREPARATIONS IN PROGRESS TO REPLACE 1-INCH O-LETS WITH 2-INCH.
A11: 46 | B11: 45785 | C11: 2025 | D11: 20250114 | E11: 41050 | F11: SUPPLEMENTAL FINAL | G11: 32099 | H11: ENERGY TRANSFER COMPANY | I11: 1300 MAIN STREET | J11: HOUSTON | K11: TX | L11: 77002 | M11: 45755.361 | N11: CENTRAL | O11: YES | P11: 32.001672 | Q11: -102.04588 | R11: CRUDE OIL | W11: 12 | Y11: 12 | Z11: NO | AF11: 0 | AG11: NO | AM11: 0 | AN11: LOCAL OPERATING PERSONNEL, INCLUDING CONTRACTORS | AP11: OPERATOR EMPLOYEE | AQ11: 45755.361 | AR11: ONSHORE TERMINAL/TANK FARM EQUIPMENT AND PIPING | AS11: ONSHORE | AT11: NORMAL OPERATION, INCLUDES PAUSES BETWEEN BATCHES AND DURING MAINTENANCE | AU11: NO | AV11: ISOLATED TANK | AZ11: NO | BC11: 45755.361 | BD11: 45755.361 | BE11: 45755.403 | BF11: 1428027 | BG11: 1428209 | BH11: NO | BV11: YES | BW11: 45755.369 | BX11: NO | CA11: 0 | CB11: MIDLAND TANK FARM | CC11: TANK 1979 16-INCH FILL LINE | CD11: TX | CE11: 79706 | CF11: Not Within a Municipality | CG11: MIDLAND | CH11: SURVEY STATION NO. | CI11: MIDLAND TF | CJ11: NO | CK11: TOTALLY CONTAINED ON OPERATOR-CONTROLLED PROPERTY | CL11: ABOVEGROUND | CM11: TYPICAL ABOVEGROUND FACILITY PIPING OR APPURTENANCE | CP11: NO | DM11: INTRASTATE | DN11: VALVE | EM11: AUXILIARY OR OTHER VALVE | FK11: 2019 | FL11: 2018 | FM11: CARBON STEEL | FO11: LEAK | FR11: PINHOLE | FY11: NO | GC11: YES | GD11: NO | GE11: YES | GH11: YES | GK11: NO | GT11: YES | GU11: NO | HF11: 0 | HG11: 293 | HH11: 19247 | HI11: 4810 | HJ11: 5590 | HK11: 0 | HM11: 29940 | HN11: 0 | HO11: 0 | HP11: 0 | HQ11: 0 | HR11: 8 | HS11: 285 | HT11: COMPONENT DESIGN PRESSURE ß195.406(A)(2) | HV11: 43783 | HW11: NO | HY11: PRESSURE DID NOT EXCEED MOP | HZ11: NO | IS11: > 20% SMYS REGULATED GATHERING | IT11: NO | IY11: NO | JD11: NO, THE FACILITY WAS NOT MONITORED BY A CONTROLLER(S) AT THE TIME OF THE ACCIDENT | JR11: NO | JS11: NO | JX11: CORROSION FAILURE | JY11: INTERNAL CORROSION | JZ11: INTERNAL CORROSION | LD11: LOCALIZED PITTING | LG11: YES | LJ11: YES | LK11: TRACES OF PRODUCED WATER AND DEBRIS IN PRODUCT STREAM | LM11: YES | LS11: YES | LT11: BOTTOM OF VALVE BODY. | LU11: NO | LV11: NO | LW11: NOT APPLICABLE - NOT MAINLINE PIPE | LX11: NOT APPLICABLE - NOT MAINLINE PIPE | XL11: TODD NARDOZZI | XM11: DIRECTOR - DOT COMPLIANCE | XN11: todd.nardozzi@energytransfer.com | XO11: 713-989-7126 | XQ11: 45826 | XU11: TODD NARDOZZI | XV11: 713-989-7126 | XW11: DIRECTOR - DOT COMPLIANCE | XX11: todd.nardozzi@energytransfer.com | XY11: ON 4/8/2025, AT APPROXIMATELY 08:40, AN OPERATOR EMPLOYEE DISCOVERED A LEAK ON THE 16INCH VALVE ON TANK LINE 1979 AT MIDLAND TANK FARM. THE LEAK WAS IMMEDIATELY ISOLATED. APPROXIMATELY 12 BARRELS OF CRUDE OIL WAS RELEASED. CLEANUP CONTRACTORS REMOVED PRODUCT AND REMEDIATED IMPACTED SOIL. THE LEAK WAS REPAIRED BY REPLACING THE VALVE. THE LINE WAS PUT BACK IN SERVICE ON 04/11/2025. THE CAUSE OF THE ACCIDENT IS STILL UNDER INVESTIGATION. A SUPPLEMENTAL REPORT WILL BE SUBMITTED ONCE THE INVESTIGATION IS COMPLETE. SUPPLEMENTAL & FINAL: THE INVESTIGATION DETERMINED THE CAUSE OF THE ACCIDENT WAS DUE TO INTERNAL CORROSION. THE LEAK COINCIDED WITHIN A REGION OF INTERNAL CORROSION LOCATED ALONG THE BOTTOM OF THE VALVE BODY. A PIT IN THE FLANGE MATERIAL ADJACENT TO THE LEAK LOCATION WAS ALSO OBSERVED, WHICH ALIGNED WITH PRE-EXISTING MANUFACTURING VOIDS. ADDITIONALLY, A SECOND PIT WAS IDENTIFIED WITHIN THE ADJACENT FLANGE MATERIAL OF THE VALVE, FURTHER CONTRIBUTING TO THE LOCALIZED CORROSION AND EVENTUAL LEAK. TO PREVENT REOCCURRENCE, NDE EXAMINE ONE OTHER VALVE BY SAME MANUFACTURER WITH SAME APPROXIMATE MANUFACTURED DATE TO ENSURE NO THINNING OF THE BODY WAS OCCURRING.
